Workbook

Sheet Inputs
A1: GASQ Assumptions & Controls
A2: GASQ-branded operating model worksheet
A3: Core Controls
A4: Direct Labor Wage ($/paid hour) | B4: 20
A5: Annual Paid Hours per FTE | B5: 1456
A6: Annual Productive Coverage Hours per FTE | B6: 1456
A7: Locality Pay % | B7: 0.174
A8: Shift Differential % | B8: 0.0076
A9: OT/Holiday Premium % | B9: 0.0423
A11: Fringe / Employer Burden
A12: FICA / Medicare % | B12: 0.0765
A13: FUTA % | B13: 0.006
A14: SUTA % | B14: 0.015
A15: Workers Compensation % | B15: 0.05
A16: Health & Welfare ($/paid hour) | B16: 5.55
A17: Vacation % | B17: 0.025
A18: Paid Holidays % | B18: 0.075
A19: Sick Leave % | B19: 0.0125
A21: Operations / Support
A22: Recruiting / Hiring % | B22: 0.015
A23: Training / Certification % | B23: 0.015
A24: Uniforms / Equipment % | B24: 0.01
A25: Field Supervision % | B25: 0.06
A26: Contract Management % | B26: 0.03
A27: Quality Assurance % | B27: 0.015
A28: Vehicles / Patrol % | B28: 0.02
A29: Technology / Systems % | B29: 0.01
A30: General Liability Insurance % | B30: 0.015
A31: Umbrella / Other Insurance % | B31: 0.0075
A33: Corporate & Pricing Controls
A34: Administrative / HR / Payroll % | B34: 0.03
A35: Accounting / Legal % | B35: 0.02
A36: Corporate Overhead % | B36: 0.12
A37: G&A % | B37: 0.06
A38: Profit / Fee % | B38: 0.08
A39: Vendor TCO Factor vs Government TCO | B39: 0.7
A40: Vendor Floor Factor vs Vendor TCO | B40: 0.7
A41: Minimum Weekly Hours for Floor Eligibility | B41: 1500
A42: Government Full Burden Labor Share | B42: 0.7
A43: Government Workforce Hours Basis | B43: 3744
...

Sheet Post_Positions
A1: GASQ Posts / Positions / Locations | T1: Controls
A2: Use AUTO mode to activate model-driven billing rates or MANUAL mode to type your own rate. AUTO logic: Auto Bill Rate = (Pay Wage ÷ labor share) × (workforce hours basis ÷ productive coverage hours); Final Bill Rate = Auto Bill Rate × labor share. This section is built as an Excel table so rows can be inserted or removed without breaking formulas. See the integrated Scope of Work block at the lower right of this tab. | T2: Std Hrs / FTE | U2: 40
T3: OT Premium (x) | U3: 1.5
T4: Summary | V4: AUTO uses Inputs!B4 | W4: MANUAL uses col V
T5: Weekly Hours | U5: =SUBTOTAL(109,Post_Positions!$E$7:$E$21) -> 964 | V5: Wage Input | W5: Control
A6: Line Item | B6: Post | C6: Position | D6: Location | E6: Weekly Hours | F6: Pay Wage ($/hr) | G6: Rate Mode | H6: Manual Bill Rate ($/hr) | I6: Auto Bill Rate ($/hr) | J6: Final Bill Rate ($/hr) | K6: Unbilled OT (% Hrs) | L6: Billed OT (% Hrs) | M6: Training Hrs | N6: Training Wage ($/hr) | O6: Weekly Pay Cost | P6: Weekly Billing | Q6: Training Cost | R6: Weekly Margin | S6: Headcount | T6: Weekly Pay Cost | U6: =SUBTOTAL(109,Post_Positions!$O$7:$O$21) -> 19280 | V6: Manual Pay Wage ($/hr) | W6: Wage Mode
A7: 1 | B7: Post 1 | C7: Armed Security Officer | E7: 168 | F7: =IF($B7="","",IF($W7="MANUAL",$V7,Inputs!$B$4)) -> 20 | G7: AUTO | H7: 45 | I7: =IF(OR(F7="",F7=0),"",((F7*(1+Inputs!$B$44))/Inputs!$B$42)*(Inputs!$B$43/Inputs!$B$6)) -> 73.469388 | J7: =IF(E7="","",IF(G7="AUTO",I7*Inputs!$B$42,H7)) -> 51.428571 | K7: 0 | L7: 0 | M7: 0 | N7: 30 | O7: =IF(OR(E7="",F7=""),"",E7*F7*(1+$U$3*(IF(K7="",0,K7)+IF(L7="",0,L7)))) -> 3360 | P7: =IF(OR(E7="",J7=""),"",E7*J7*(1+IF(L7="",0,L7))) -> 8640 | Q7: =IF(OR(M7="",N7=""),"",M7*N7) -> 0 | R7: =IF(OR(O7="",P7=""),"",P7-O7-IF(Q7="",0,Q7)) -> 5280 | S7: =IF(E7="","",ROUNDUP(E7/28,0)) -> 6 | T7: Weekly Billing | U7: =SUBTOTAL(109,Post_Positions!$P$7:$P$21) -> 49577.143 | V7: 67 | W7: AUTO
A8: 2 | B8: Post 2 | C8: Security Officer I | E8: 168 | F8: =IF($B8="","",IF($W8="MANUAL",$V8,Inputs!$B$4)) -> 20 | G8: AUTO | H8: 45 | I8: =IF(OR(F8="",F8=0),"",((F8*(1+Inputs!$B$44))/Inputs!$B$42)*(Inputs!$B$43/Inputs!$B$6)) -> 73.469388 | J8: =IF(E8="","",IF(G8="AUTO",I8*Inputs!$B$42,H8)) -> 51.428571 | K8: 0 | L8: 0 | M8: 0 | N8: 30 | O8: =IF(OR(E8="",F8=""),"",E8*F8*(1+$U$3*(IF(K8="",0,K8)+IF(L8="",0,L8)))) -> 3360 | P8: =IF(OR(E8="",J8=""),"",E8*J8*(1+IF(L8="",0,L8))) -> 8640 | Q8: =IF(OR(M8="",N8=""),"",M8*N8) -> 0 | R8: =IF(OR(O8="",P8=""),"",P8-O8-IF(Q8="",0,Q8)) -> 5280 | S8: =IF(E8="","",ROUNDUP(E8/28,0)) -> 6 | T8: Training Cost | U8: =SUBTOTAL(109,Post_Positions!$Q$7:$Q$21) -> 0 | W8: AUTO
A9: 3 | B9: Post 3 | C9: Security Officer II | E9: 168 | F9: =IF($B9="","",IF($W9="MANUAL",$V9,Inputs!$B$4)) -> 20 | G9: AUTO | H9: 45 | I9: =IF(OR(F9="",F9=0),"",((F9*(1+Inputs!$B$44))/Inputs!$B$42)*(Inputs!$B$43/Inputs!$B$6)) -> 73.469388 | J9: =IF(E9="","",IF(G9="AUTO",I9*Inputs!$B$42,H9)) -> 51.428571 | K9: 0 | L9: 0 | M9: 0 | N9: 30 | O9: =IF(OR(E9="",F9=""),"",E9*F9*(1+$U$3*(IF(K9="",0,K9)+IF(L9="",0,L9)))) -> 3360 | P9: =IF(OR(E9="",J9=""),"",E9*J9*(1+IF(L9="",0,L9))) -> 8640 | Q9: =IF(OR(M9="",N9=""),"",M9*N9) -> 0 | R9: =IF(OR(O9="",P9=""),"",P9-O9-IF(Q9="",0,Q9)) -> 5280 | S9: =IF(E9="","",ROUNDUP(E9/28,0)) -> 6 | T9: Weekly Margin | U9: =SUBTOTAL(109,Post_Positions!$R$7:$R$21) -> 30297.143 | W9: AUTO
A10: 4 | B10: Post 4 | E10: 168 | F10: =IF($B10="","",IF($W10="MANUAL",$V10,Inputs!$B$4)) -> 20 | G10: AUTO | H10: 45 | I10: =IF(OR(F10="",F10=0),"",((F10*(1+Inputs!$B$44))/Inputs!$B$42)*(Inputs!$B$43/Inputs!$B$6)) -> 73.469388 | J10: =IF(E10="","",IF(G10="AUTO",I10*Inputs!$B$42,H10)) -> 51.428571 | O10: =IF(OR(E10="",F10=""),"",E10*F10*(1+$U$3*(IF(K10="",0,K10)+IF(L10="",0,L10)))) -> 3360 | P10: =IF(OR(E10="",J10=""),"",E10*J10*(1+IF(L10="",0,L10))) -> 8640 | Q10: =IF(OR(M10="",N10=""),"",M10*N10) | R10: =IF(OR(O10="",P10=""),"",P10-O10-IF(Q10="",0,Q10)) -> 5280 | S10: =IF(E10="","",ROUNDUP(E10/28,0)) -> 6 | T10: Headcount | U10: =SUBTOTAL(109,Post_Positions!$S$7:$S$21) -> 35 | W10: AUTO
A11: 5 | B11: Post 5 | E11: 112 | F11: =IF($B11="","",IF($W11="MANUAL",$V11,Inputs!$B$4)) -> 20 | G11: AUTO | H11: 45 | I11: =IF(OR(F11="",F11=0),"",((F11*(1+Inputs!$B$44))/Inputs!$B$42)*(Inputs!$B$43/Inputs!$B$6)) -> 73.469388 | J11: =IF(E11="","",IF(G11="AUTO",I11*Inputs!$B$42,H11)) -> 51.428571 | O11: =IF(OR(E11="",F11=""),"",E11*F11*(1+$U$3*(IF(K11="",0,K11)+IF(L11="",0,L11)))) -> 2240 | P11: =IF(OR(E11="",J11=""),"",E11*J11*(1+IF(L11="",0,L11))) -> 5760 | Q11: =IF(OR(M11="",N11=""),"",M11*N11) | R11: =IF(OR(O11="",P11=""),"",P11-O11-IF(Q11="",0,Q11)) -> 3520 | S11: =IF(E11="","",ROUNDUP(E11/28,0)) -> 4 | T11: AUTO rate = ((Pay Wage × (1 + Inputs!B44 locality pay)) ÷ Inputs!B42 labor share) × (Inputs!B43 workforce hours basis ÷ Inputs!B6 productive coverage hours). Final Bill Rate switches automatically based on Rate Mode. | W11: AUTO
A12: 6 | B12: Post 6 | E12: 40 | F12: =IF($B12="","",IF($W12="MANUAL",$V12,Inputs!$B$4)) -> 20 | G12: AUTO | H12: 45 | I12: =IF(OR(F12="",F12=0),"",((F12*(1+Inputs!$B$44))/Inputs!$B$42)*(Inputs!$B$43/Inputs!$B$6)) -> 73.469388 | J12: =IF(E12="","",IF(G12="AUTO",I12*Inputs!$B$42,H12)) -> 51.428571 | O12: =IF(OR(E12="",F12=""),"",E12*F12*(1+$U$3*(IF(K12="",0,K12)+IF(L12="",0,L12)))) -> 800 | P12: =IF(OR(E12="",J12=""),"",E12*J12*(1+IF(L12="",0,L12))) -> 2057.1429 | Q12: =IF(OR(M12="",N12=""),"",M12*N12) | R12: =IF(OR(O12="",P12=""),"",P12-O12-IF(Q12="",0,Q12)) -> 1257.1429 | S12: =IF(E12="","",ROUNDUP(E12/28,0)) -> 2 | W12: AUTO
A13: 7 | B13: Post 7 | E13: 56 | F13: =IF($B13="","",IF($W13="MANUAL",$V13,Inputs!$B$4)) -> 20 | G13: AUTO | H13: 45 | I13: =IF(OR(F13="",F13=0),"",((F13*(1+Inputs!$B$44))/Inputs!$B$42)*(Inputs!$B$43/Inputs!$B$6)) -> 73.469388 | J13: =IF(E13="","",IF(G13="AUTO",I13*Inputs!$B$42,H13)) -> 51.428571 | O13: =IF(OR(E13="",F13=""),"",E13*F13*(1+$U$3*(IF(K13="",0,K13)+IF(L13="",0,L13)))) -> 1120 | P13: =IF(OR(E13="",J13=""),"",E13*J13*(1+IF(L13="",0,L13))) -> 2880 | Q13: =IF(OR(M13="",N13=""),"",M13*N13) | R13: =IF(OR(O13="",P13=""),"",P13-O13-IF(Q13="",0,Q13)) -> 1760 | S13: =IF(E13="","",ROUNDUP(E13/28,0)) -> 2 | T13: Annual Hours | U13: =IF(U5="","",U5*52) -> 50128 | W13: AUTO
A14: 8 | B14: Post 8 | E14: 84 | F14: =IF($B14="","",IF($W14="MANUAL",$V14,Inputs!$B$4)) -> 20 | G14: AUTO | H14: 45 | I14: =IF(OR(F14="",F14=0),"",((F14*(1+Inputs!$B$44))/Inputs!$B$42)*(Inputs!$B$43/Inputs!$B$6)) -> 73.469388 | J14: =IF(E14="","",IF(G14="AUTO",I14*Inputs!$B$42,H14)) -> 51.428571 | O14: =IF(OR(E14="",F14=""),"",E14*F14*(1+$U$3*(IF(K14="",0,K14)+IF(L14="",0,L14)))) -> 1680 | P14: =IF(OR(E14="",J14=""),"",E14*J14*(1+IF(L14="",0,L14))) -> 4320 | Q14: =IF(OR(M14="",N14=""),"",M14*N14) | R14: =IF(OR(O14="",P14=""),"",P14-O14-IF(Q14="",0,Q14)) -> 2640 | S14: =IF(E14="","",ROUNDUP(E14/28,0)) -> 3 | T14: Blended Direct Wage | U14: =IFERROR(SUMPRODUCT($E$7:$E$21,$F$7:$F$21)/$U$5,"") -> 20 | W14: AUTO
A15: 9 | B15: Post 9 | F15: =IF($B15="","",IF($W15="MANUAL",$V15,Inputs!$B$4)) -> 20 | I15: =IF(OR(F15="",F15=0),"",((F15*(1+Inputs!$B$44))/Inputs!$B$42)*(Inputs!$B$43/Inputs!$B$6)) -> 73.469388 | J15: =IF(E15="","",IF(G15="AUTO",I15*Inputs!$B$42,H15)) | O15: =IF(OR(E15="",F15=""),"",E15*F15*(1+$U$3*(IF(K15="",0,K15)+IF(L15="",0,L15)))) | P15: =IF(OR(E15="",J15=""),"",E15*J15*(1+IF(L15="",0,L15))) | Q15: =IF(OR(M15="",N15=""),"",M15*N15) | R15: =IF(OR(O15="",P15=""),"",P15-O15-IF(Q15="",0,Q15)) | S15: =IF(E15="","",ROUNDUP(E15/28,0)) | T15: Blended Bill Rate | U15: =IFERROR(U7/U5,"") -> 51.428571 | W15: AUTO
A16: 10 | B16: Post 10 | F16: =IF($B16="","",IF($W16="MANUAL",$V16,Inputs!$B$4)) -> 20 | I16: =IF(OR(F16="",F16=0),"",((F16*(1+Inputs!$B$44))/Inputs!$B$42)*(Inputs!$B$43/Inputs!$B$6)) -> 73.469388 | J16: =IF(E16="","",IF(G16="AUTO",I16*Inputs!$B$42,H16)) | O16: =IF(OR(E16="",F16=""),"",E16*F16*(1+$U$3*(IF(K16="",0,K16)+IF(L16="",0,L16)))) | P16: =IF(OR(E16="",J16=""),"",E16*J16*(1+IF(L16="",0,L16))) | Q16: =IF(OR(M16="",N16=""),"",M16*N16) | R16: =IF(OR(O16="",P16=""),"",P16-O16-IF(Q16="",0,Q16)) | S16: =IF(E16="","",ROUNDUP(E16/28,0)) | T16: Annual Billings | U16: =IF(U7="","",U7*52) -> 2578011.4 | W16: AUTO
A17: 11 | B17: Post 11 | F17: =IF($B17="","",IF($W17="MANUAL",$V17,Inputs!$B$4)) -> 20 | I17: =IF(OR(F17="",F17=0),"",((F17*(1+Inputs!$B$44))/Inputs!$B$42)*(Inputs!$B$43/Inputs!$B$6)) -> 73.469388 | J17: =IF(E17="","",IF(G17="AUTO",I17*Inputs!$B$42,H17)) | O17: =IF(OR(E17="",F17=""),"",E17*F17*(1+$U$3*(IF(K17="",0,K17)+IF(L17="",0,L17)))) | P17: =IF(OR(E17="",J17=""),"",E17*J17*(1+IF(L17="",0,L17))) | Q17: =IF(OR(M17="",N17=""),"",M17*N17) | R17: =IF(OR(O17="",P17=""),"",P17-O17-IF(Q17="",0,Q17)) | S17: =IF(E17="","",ROUNDUP(E17/28,0)) | T17: Annual Pay Cost | U17: =IF(U6="","",U6*52) -> 1002560 | W17: AUTO
A18: 12 | B18: Post 12 | F18: =IF($B18="","",IF($W18="MANUAL",$V18,Inputs!$B$4)) -> 20 | I18: =IF(OR(F18="",F18=0),"",((F18*(1+Inputs!$B$44))/Inputs!$B$42)*(Inputs!$B$43/Inputs!$B$6)) -> 73.469388 | J18: =IF(E18="","",IF(G18="AUTO",I18*Inputs!$B$42,H18)) | O18: =IF(OR(E18="",F18=""),"",E18*F18*(1+$U$3*(IF(K18="",0,K18)+IF(L18="",0,L18)))) | P18: =IF(OR(E18="",J18=""),"",E18*J18*(1+IF(L18="",0,L18))) | Q18: =IF(OR(M18="",N18=""),"",M18*N18) | R18: =IF(OR(O18="",P18=""),"",P18-O18-IF(Q18="",0,Q18)) | S18: =IF(E18="","",ROUNDUP(E18/28,0)) | T18: Annual Training Cost | U18: =IF(U8="","",U8*52) -> 0 | W18: AUTO
A19: 13 | B19: Post 13 | F19: =IF($B19="","",IF($W19="MANUAL",$V19,Inputs!$B$4)) -> 20 | I19: =IF(OR(F19="",F19=0),"",((F19*(1+Inputs!$B$44))/Inputs!$B$42)*(Inputs!$B$43/Inputs!$B$6)) -> 73.469388 | J19: =IF(E19="","",IF(G19="AUTO",I19*Inputs!$B$42,H19)) | O19: =IF(OR(E19="",F19=""),"",E19*F19*(1+$U$3*(IF(K19="",0,K19)+IF(L19="",0,L19)))) | P19: =IF(OR(E19="",J19=""),"",E19*J19*(1+IF(L19="",0,L19))) | Q19: =IF(OR(M19="",N19=""),"",M19*N19) | R19: =IF(OR(O19="",P19=""),"",P19-O19-IF(Q19="",0,Q19)) | S19: =IF(E19="","",ROUNDUP(E19/28,0)) | T19: Annual Margin | U19: =IF(U9="","",U9*52) -> 1575451.4 | W19: AUTO
A20: 14 | B20: Post 14 | F20: =IF($B20="","",IF($W20="MANUAL",$V20,Inputs!$B$4)) -> 20 | I20: =IF(OR(F20="",F20=0),"",((F20*(1+Inputs!$B$44))/Inputs!$B$42)*(Inputs!$B$43/Inputs!$B$6)) -> 73.469388 | J20: =IF(E20="","",IF(G20="AUTO",I20*Inputs!$B$42,H20)) | O20: =IF(OR(E20="",F20=""),"",E20*F20*(1+$U$3*(IF(K20="",0,K20)+IF(L20="",0,L20)))) | P20: =IF(OR(E20="",J20=""),"",E20*J20*(1+IF(L20="",0,L20))) | Q20: =IF(OR(M20="",N20=""),"",M20*N20) | R20: =IF(OR(O20="",P20=""),"",P20-O20-IF(Q20="",0,Q20)) | S20: =IF(E20="","",ROUNDUP(E20/28,0)) | T20: Actual vs Target Rate | U20: =IFERROR(U15-Vendor_Pricing!B7,"") -> 7.7142857 | W20: AUTO
A21: 15 | B21: Post 15 | F21: =IF($B21="","",IF($W21="MANUAL",$V21,Inputs!$B$4)) -> 20 | I21: =IF(OR(F21="",F21=0),"",((F21*(1+Inputs!$B$44))/Inputs!$B$42)*(Inputs!$B$43/Inputs!$B$6)) -> 73.469388 | J21: =IF(E21="","",IF(G21="AUTO",I21*Inputs!$B$42,H21)) | O21: =IF(OR(E21="",F21=""),"",E21*F21*(1+$U$3*(IF(K21="",0,K21)+IF(L21="",0,L21)))) | P21: =IF(OR(E21="",J21=""),"",E21*J21*(1+IF(L21="",0,L21))) | Q21: =IF(OR(M21="",N21=""),"",M21*N21) | R21: =IF(OR(O21="",P21=""),"",P21-O21-IF(Q21="",0,Q21)) | S21: =IF(E21="","",ROUNDUP(E21/28,0)) | T21: Feed Status | U21: =IF(U5>0,"ACTIVE - pricing tabs linked to Post_Positions","INACTIVE - using manual worksheet inputs") -> ACTIVE - pricing tabs linked to Post_Positions | W21: AUTO
A22: Totals | E22: =SUBTOTAL(109,Post_Positions!$E$7:$E$21) -> 964 | O22: =SUBTOTAL(109,Post_Positions!$O$7:$O$21) -> 19280 | P22: =SUBTOTAL(109,Post_Positions!$P$7:$P$21) -> 49577.143 | Q22: =SUBTOTAL(109,Post_Positions!$Q$7:$Q$21) -> 0 | R22: =SUBTOTAL(109,Post_Positions!$R$7:$R$21) -> 30297.143 | S22: =SUBTOTAL(109,Post_Positions!$S$7:$S$21) -> 35 | T22: Annual Coverage Hours | U22: =X33 -> 8736
T23: Weekly Labor Hours | U23: =X36 -> 964
T24: Annual Labor Hours | U24: =X37 -> 50128 | W24: GASQ Scope of Work (Integrated with Post / Positions)
T25: FTEs Required | U25: =X38 -> 34.428571 | W25: Edit scope inputs here; staffing metrics update automatically and remain mirrored on the Scope_of_Work tab.
W26: User Inputs
W27: Hours of Coverage per Day | X27: 24
W28: Days of Coverage per Week | X28: 7
W29: Weeks of Coverage | X29: 52
W30: Staff per 8-Hour Shift | X30: 1
W32: Calculated Staffing Metrics
W33: Annual Coverage Hours | X33: =X27*X28*X29*X30 -> 8736
W34: 8-Hour Shifts per Day | X34: =X27/8 -> 3
W35: Daily Labor Hours | X35: =X27*X30 -> 24
W36: Weekly Labor Hours | X36: =IF(Post_Positions!$U$5>0,Post_Positions!$U$5,X27*X28*X30) -> 964
W37: Annual Labor Hours | X37: =IF(Post_Positions!$U$5>0,Post_Positions!$U$13,X33) -> 50128
W38: FTEs Required @ Paid Hours Basis | X38: =IFERROR(X37/Inputs!$B$5,0) -> 34.428571
W39: Coverage-to-FTE Ratio | X39: =IFERROR(X37/Inputs!$B$6,0) -> 34.428571
W41: Notes

Sheet Scope_of_Work
A1: GASQ Scope of Work
A2: Primary Scope of Work inputs are now integrated on the Post_Positions tab; this sheet mirrors those values.
A3: Linked View (edit on Post_Positions)
A4: Hours of Coverage per Day | B4: =Post_Positions!$X$27 -> 24
A5: Days of Coverage per Week | B5: =Post_Positions!$X$28 -> 7
A6: Weeks of Coverage | B6: =Post_Positions!$X$29 -> 52
A7: Staff per 8-Hour Shift | B7: =Post_Positions!$X$30 -> 1
A9: Calculated Staffing Metrics
A10: Annual Coverage Hours | B10: =Post_Positions!$X$33 -> 8736
A11: 8-Hour Shifts per Day | B11: =Post_Positions!$X$34 -> 3
A12: Daily Labor Hours | B12: =Post_Positions!$X$35 -> 24
A13: Weekly Labor Hours | B13: =Post_Positions!$X$36 -> 964
A14: Annual Labor Hours | B14: =Post_Positions!$X$37 -> 50128
A15: FTEs Required @ Paid Hours Basis | B15: =Post_Positions!$X$38 -> 34.428571
A16: Coverage-to-FTE Ratio | B16: =Post_Positions!$X$39 -> 34.428571
A18: Notes
A19: Linked mirror. Edit the integrated Scope of Work block on Post_Positions.

Sheet Direct_Labor
A1: GASQ Direct Labor Build-Up
A2: GASQ-branded operating model worksheet
A3: Line Item | B3: Input / Formula | C3: Hourly Amount | D3: Annual Amount
A4: Base Direct Labor Wage | B4: =Inputs!B4 -> 20 | C4: =Inputs!B4 -> 20 | D4: =C4*Scope_of_Work!$B$14 -> 1002560
A5: Locality Pay | B5: =Inputs!B4*Inputs!B7 -> 3.48 | C5: =B5 -> 3.48 | D5: =C5*Scope_of_Work!$B$14 -> 174445.44
A6: Shift Differential | B6: =Inputs!B4*Inputs!B8 -> 0.152 | C6: =B6 -> 0.152 | D6: =C6*Scope_of_Work!$B$14 -> 7619.456
A7: OT/Holiday Premium | B7: =Inputs!B4*Inputs!B9 -> 0.846 | C7: =B7 -> 0.846 | D7: =C7*Scope_of_Work!$B$14 -> 42408.288
A8: Total Direct Labor | C8: =SUM(C4:C7) -> 24.478 | D8: =SUM(D4:D7) -> 1227033.2
A9: Direct labor wage now mirrors the direct labor wage input (or weighted blended pay wage from Post_Positions only), before premiums and burden are applied. | C9: =C8 -> 24.478 | D9: =D8 -> 1227033.2

Sheet Fringe_Costs
A1: GASQ Fringe & Employer Burden
A2: GASQ-branded operating model worksheet
A3: Line Item | B3: Input / Formula | C3: Hourly Amount | D3: Annual Amount
A4: FICA / Medicare | B4: =Direct_Labor!$C$8*Inputs!B12 -> 1.872567 | C4: =B4 -> 1.872567 | D4: =C4*Scope_of_Work!$B$14 -> 93868.039
A5: FUTA | B5: =Direct_Labor!$C$8*Inputs!B13 -> 0.146868 | C5: =B5 -> 0.146868 | D5: =C5*Scope_of_Work!$B$14 -> 7362.1991
A6: SUTA | B6: =Direct_Labor!$C$8*Inputs!B14 -> 0.36717 | C6: =B6 -> 0.36717 | D6: =C6*Scope_of_Work!$B$14 -> 18405.498
A7: Workers Compensation | B7: =Direct_Labor!$C$8*Inputs!B15 -> 1.2239 | C7: =B7 -> 1.2239 | D7: =C7*Scope_of_Work!$B$14 -> 61351.659
A8: Health & Welfare | B8: =Inputs!B16 -> 5.55 | C8: =B8 -> 5.55 | D8: =C8*Scope_of_Work!$B$14 -> 278210.4
A9: Vacation | B9: =Direct_Labor!$C$8*Inputs!B17 -> 0.61195 | C9: =B9 -> 0.61195 | D9: =C9*Scope_of_Work!$B$14 -> 30675.83
A10: Paid Holidays | B10: =Direct_Labor!$C$8*Inputs!B18 -> 1.83585 | C10: =B10 -> 1.83585 | D10: =C10*Scope_of_Work!$B$14 -> 92027.489
A11: Sick Leave | B11: =Direct_Labor!$C$8*Inputs!B19 -> 0.305975 | C11: =B11 -> 0.305975 | D11: =C11*Scope_of_Work!$B$14 -> 15337.915
A12: Total Fringe / Burden | C12: =SUM(C4:C11) -> 11.91428 | D12: =SUM(D4:D11) -> 597239.03

Sheet Vehicle
A1: GASQ Vehicle / Patrol Cost Model
A2: GASQ-branded operating model worksheet
A3: Vehicle Assumptions
A4: Line Item | B4: Input / Formula | C4: Units | D4: Notes
A5: Vehicles Required | B5: 2 | C5: vehicles | D5: User input
A6: Average Miles per Vehicle per Day | B6: 365 | C6: miles/day | D6: User input
A7: Operating Days per Week | B7: =Scope_of_Work!B5 -> 7 | C7: days/week | D7: Linked from scope
A8: Weeks of Coverage | B8: =Scope_of_Work!B6 -> 52 | C8: weeks/year | D8: Linked from scope
A9: Fuel Economy | B9: 22 | C9: mpg | D9: User input
A10: Fuel Cost per Gallon | B10: 4 | C10: $/gallon | D10: User input
A11: Maintenance Cost per Mile | B11: 0.18 | C11: $/mile | D11: User input
A12: Monthly Lease / Payment per Vehicle | B12: 850 | C12: $/month | D12: User input
A13: Monthly Insurance per Vehicle | B13: 225 | C13: $/month | D13: User input
A14: Monthly GPS / Telematics per Vehicle | B14: 1 | C14: $/month | D14: User input
A15: Annual Registration / Tags per Vehicle | B15: 250 | C15: $/year | D15: User input
A18: Vehicle Cost Calculations
A19: Metric | B19: Formula | C19: Result | D19: Units
A20: Daily Fleet Miles | B20: =B5*B6 -> 730 | C20: =B20 -> 730 | D20: miles/day
A21: Annual Fleet Miles | B21: =C20*B7*B8 -> 265720 | C21: =B21 -> 265720 | D21: miles/year
A22: Annual Fuel Gallons | B22: =IFERROR(C21/B9,0) -> 12078.182 | C22: =B22 -> 12078.182 | D22: gallons/year
A23: Annual Fuel Cost | B23: =C22*B10 -> 48312.727 | C23: =B23 -> 48312.727 | D23: $/year
A24: Annual Maintenance Cost | B24: =C21*B11 -> 47829.6 | C24: =B24 -> 47829.6 | D24: $/year
A25: Annual Lease / Payment Cost | B25: =B5*B12*12 -> 20400 | C25: =B25 -> 20400 | D25: $/year
A26: Annual Insurance Cost | B26: =B5*B13*12 -> 5400 | C26: =B26 -> 5400 | D26: $/year
A27: Annual GPS / Telematics Cost | B27: =B5*B14*12 -> 24 | C27: =B27 -> 24 | D27: $/year
A28: Annual Registration / Tags | B28: =B5*B15 -> 500 | C28: =B28 -> 500 | D28: $/year
A29: Total Annual Vehicle Cost | B29: =SUM(C23:C28) -> 122466.33 | C29: =B29 -> 122466.33 | D29: $/year
A30: Vehicle Cost per Annual Labor Hour | B30: =IFERROR(C29/Scope_of_Work!B14,0) -> 2.4430723 | C30: =B30 -> 2.4430723 | D30: $/labor hr
A31: Vehicle Cost per Productive Coverage Hour | B31: =IFERROR(C29/Scope_of_Work!B14,0) -> 2.4430723 | C31: =B31 -> 2.4430723 | D31: $/coverage hr
A34: This tab calculates annual fleet cost and converts it into an hourly rate that feeds the Operations tab.

Sheet Uniform_Equipment
A1: GASQ Uniform & Equipment Module
A2: GASQ-branded operating model worksheet
A3: Program Inputs
A4: Input / Line Item | B4: Value | C4: Units | D4: Calc / Annualized | E4: Notes
A5: FTEs Required | B5: =ROUNDUP(Scope_of_Work!B15,0) -> 35 | C5: FTEs | E5: Linked from Scope_of_Work
A6: Annual Labor Hours | B6: =Scope_of_Work!B14 -> 50128 | C6: hours | E6: Linked from Scope_of_Work
A7: Uniform Sets per Employee | B7: 3 | C7: sets/FTE | E7: Hardcoded input
A8: Cost per Uniform Set | B8: 225 | C8: $ / set | E8: Hardcoded input
A9: Uniform Useful Life | B9: 12 | C9: months | E9: Annual issue if 12 months
A10: Duty Gear Kit per Employee | B10: 350 | C10: $ / FTE | E10: Belts, pouches, accessories
A11: Duty Gear Useful Life | B11: 24 | C11: months | E11: Annualized over useful life
A12: Radio / Device per Employee | B12: 275 | C12: $ / FTE | E12: Phones, radios, chargers
A13: Radio / Device Useful Life | B13: 36 | C13: months | E13: Annualized over useful life
A14: Badge / ID / Misc. Issue per Employee | B14: 45 | C14: $ / FTE | E14: Initial issue
A15: Badge / ID Useful Life | B15: 12 | C15: months | E15: Annualized over useful life
A16: Annual Consumables / Small Equipment | B16: 85 | C16: $ / FTE / year | E16: Gloves, batteries, notebooks
A17: Spare / Float Inventory Factor | B17: 0.1 | C17: % | E17: Reserve for extras, turnover
A18: Program Management / Logistics Factor | B18: 0.05 | C18: % | E18: Sizing and replacement admin
A21: Annual Cost Build
A22: Metric | B22: Formula | C22: Result | D22: Units | E22: Comment
A23: Initial Uniform Issue | B23: =B5*B7*B8 -> 23625 | C23: =B23 -> 23625 | D23: $ | E23: FTEs × sets × cost
A24: Annual Uniform Cost | B24: =IFERROR(C23*(12/B9),0) -> 23625 | C24: =B24 -> 23625 | D24: $ / year | E24: Annualized by useful life
A25: Initial Duty Gear Issue | B25: =B5*B10 -> 12250 | C25: =B25 -> 12250 | D25: $ | E25: FTEs × kit cost
A26: Annual Duty Gear Cost | B26: =IFERROR(C25*(12/B11),0) -> 6125 | C26: =B26 -> 6125 | D26: $ / year | E26: Annualized by useful life
A27: Initial Radio / Device Issue | B27: =B5*B12 -> 9625 | C27: =B27 -> 9625 | D27: $ | E27: FTEs × device cost
A28: Annual Radio / Device Cost | B28: =IFERROR(C27*(12/B13),0) -> 3208.3333 | C28: =B28 -> 3208.3333 | D28: $ / year | E28: Annualized by useful life
A29: Initial Badge / ID / Misc. Issue | B29: =B5*B14 -> 1575 | C29: =B29 -> 1575 | D29: $ | E29: FTEs × issue cost
A30: Annual Badge / ID / Misc. Cost | B30: =IFERROR(C29*(12/B15),0) -> 1575 | C30: =B30 -> 1575 | D30: $ / year | E30: Annualized by useful life
A31: Annual Consumables | B31: =B5*B16 -> 2975 | C31: =B31 -> 2975 | D31: $ / year | E31: Direct annual cost
A32: Subtotal Annual Equipment Cost | B32: =SUM(C24,C26,C28,C30,C31) -> 37508.333 | C32: =B32 -> 37508.333 | D32: $ / year | E32: Before reserve and logistics
A33: Spare / Float Inventory Cost | B33: =C32*B17 -> 3750.8333 | C33: =B33 -> 3750.8333 | D33: $ / year | E33: Reserve factor
A34: Program Management / Logistics | B34: =SUM(C32:C33)*B18 -> 2062.9583 | C34: =B34 -> 2062.9583 | D34: $ / year | E34: Sizing, shipping, admin
A35: Total Annual Uniform & Equipment Cost | B35: =SUM(C32:C34) -> 43322.125 | C35: =B35 -> 43322.125 | D35: $ / year | E35: Feeds Operations tab
A36: Uniform & Equipment Cost per Labor Hour | B36: =IFERROR(C35/B6,0) -> 0.86423007 | C36: =B36 -> 0.86423007 | D36: $ / labor hour | E36: Feeds Operations hourly rate
A39: Module Checks
A40: Check | B40: Formula | C40: Result | D40: Status
A41: FTE link populated | B41: =IF(B5>0,"OK","CHECK") -> OK | C41: =B41 -> OK | D41: Scope link
A42: Annual labor hours populated | B42: =IF(B6>0,"OK","CHECK") -> OK | C42: =B42 -> OK | D42: Scope link
A43: Hourly cost available | B43: =IF(C36>=0,"OK","CHECK") -> OK | C43: =B43 -> OK | D43: Operations feed
A46: This replacement module annualizes uniforms, duty gear, devices, ID issue, and consumables, then converts the total into a cost per labor hour for the Operations tab.

Sheet Operations
A1: GASQ Operations & Contract Support
A2: GASQ-branded operating model worksheet
A3: Line Item | B3: Input / Formula | C3: Hourly Amount | D3: Annual Amount
A4: Recruiting / Hiring | B4: =Direct_Labor!$C$8*Inputs!B22 -> 0.36717 | C4: =B4 -> 0.36717 | D4: =C4*Scope_of_Work!$B$14 -> 18405.498
A5: Training / Certification | B5: =Direct_Labor!$C$8*Inputs!B23 -> 0.36717 | C5: =B5 -> 0.36717 | D5: =C5*Scope_of_Work!$B$14 -> 18405.498
A6: Uniforms / Equipment | B6: =Uniform_Equipment!$C$36 -> 0.86423007 | C6: =B6 -> 0.86423007 | D6: =Uniform_Equipment!$C$35 -> 43322.125
A7: Field Supervision | B7: =Direct_Labor!$C$8*Inputs!B25 -> 1.46868 | C7: =B7 -> 1.46868 | D7: =C7*Scope_of_Work!$B$14 -> 73621.991
A8: Contract Management | B8: =Direct_Labor!$C$8*Inputs!B26 -> 0.73434 | C8: =B8 -> 0.73434 | D8: =C8*Scope_of_Work!$B$14 -> 36810.996
A9: Quality Assurance | B9: =Direct_Labor!$C$8*Inputs!B27 -> 0.36717 | C9: =B9 -> 0.36717 | D9: =C9*Scope_of_Work!$B$14 -> 18405.498
A10: Vehicles / Patrol | B10: =Vehicle!$C$30 -> 2.4430723 | C10: =B10 -> 2.4430723 | D10: =Vehicle!$C$29 -> 122466.33
A11: Technology / Systems | B11: =Direct_Labor!$C$8*Inputs!B29 -> 0.24478 | C11: =B11 -> 0.24478 | D11: =C11*Scope_of_Work!$B$14 -> 12270.332
A12: General Liability Insurance | B12: =Direct_Labor!$C$8*Inputs!B30 -> 0.36717 | C12: =B12 -> 0.36717 | D12: =C12*Scope_of_Work!$B$14 -> 18405.498
A13: Umbrella / Other Insurance | B13: =Direct_Labor!$C$8*Inputs!B31 -> 0.183585 | C13: =B13 -> 0.183585 | D13: =C13*Scope_of_Work!$B$14 -> 9202.7489
A14: Total Operations / Support | C14: =SUM(C4:C13) -> 7.4073674 | D14: =SUM(D4:D13) -> 371316.51

Sheet Government_TCO
A1: GASQ Should-Cost TCO & Capital Recovery Engine
A2: Uses the GASQ labor-share framework to translate direct labor into government TCO and capital recovery savings.
A3: Government TCO Formula Engine
A4: Blended Direct Labor Wage / Pay Rate | B4: =IF(IFERROR(Post_Positions!$U$5,0)>0,Post_Positions!$U$14,Inputs!$B$4) -> 20
A5: Full Burdened Hourly Cost | B5: =IFERROR(B4/Inputs!B42,0) -> 28.571429
A6: Annual Workforce Hours Basis | B6: =Inputs!B43 -> 3744
A7: Annual Workforce Cost | B7: =B5*B6 -> 106971.43
A8: Government TCO per Productive Coverage Hour | B8: =IFERROR(B7/Inputs!$B$5,0) -> 73.469388
A9: Vendor Rate | B9: =B8*Inputs!B39 -> 51.428571
A10: Capital Recovery Saved per Hour | B10: =B8-B9 -> 22.040816
A11: Annual Coverage Hours Required | B11: =IF(IFERROR(Post_Positions!$U$5,0)>0,Post_Positions!$U$13,Scope_of_Work!B14) -> 50128
A12: Annual Government Cost for Required Coverage | B12: =B8*B11 -> 3682873.5
A13: Annual Vendor Cost for Required Coverage | B13: =B9*B11 -> 2578011.4
A14: Workforce-to-Post Metrics
A15: Annual Capital Recovery Saved | B15: =B10*B11 -> 1104862
A16: Direct Labor to Government TCO Multiplier | B16: =IFERROR(B8/B4,0) -> 3.6734694
A17: Direct Labor to Vendor Rate Multiplier | B17: =IFERROR(B9/B4,0) -> 2.5714286
A18: Government Full Burden Labor Share | B18: =Inputs!B42 -> 0.7
A19: Government Workforce Hours Basis | B19: =Inputs!B43 -> 3744
A20: Model Note | B20: This tab uses Total Direct Labor from Direct_Labor!C8, then forces burden to a 70/30 labor-share model.
A22: Automatic Burden Allocation (forced to 30% of total cost)
A23: Line Item | B23: Raw Weight | C23: Normalized Share | D23: Hourly Burden | E23: Annual Burden
A24: FICA / Medicare | B24: =Inputs!B12 -> 0.0765 | C24: =IFERROR(B24/$B$36,0) -> 0.1233871 | D24: =$D$37*C24 -> 1.0576037 | E24: =D24*$B$11 -> 53015.558
A25: FUTA | B25: =Inputs!B13 -> 0.006 | C25: =IFERROR(B25/$B$36,0) -> 0.0096774194 | D25: =$D$37*C25 -> 0.082949309 | E25: =D25*$B$11 -> 4158.0829
A26: SUTA | B26: =Inputs!B14 -> 0.015 | C26: =IFERROR(B26/$B$36,0) -> 0.024193548 | D26: =$D$37*C26 -> 0.20737327 | E26: =D26*$B$11 -> 10395.207
A27: Workers Compensation | B27: =Inputs!B15 -> 0.05 | C27: =IFERROR(B27/$B$36,0) -> 0.080645161 | D27: =$D$37*C27 -> 0.69124424 | E27: =D27*$B$11 -> 34650.691
A28: Health & Welfare proxy | B28: =IFERROR(Inputs!B16/$B$4,0) -> 0.2775 | C28: =IFERROR(B28/$B$36,0) -> 0.44758065 | D28: =$D$37*C28 -> 3.8364055 | E28: =D28*$B$11 -> 192311.34
A29: Vacation | B29: =Inputs!B17 -> 0.025 | C29: =IFERROR(B29/$B$36,0) -> 0.040322581 | D29: =$D$37*C29 -> 0.34562212 | E29: =D29*$B$11 -> 17325.346
A30: Paid Holidays | B30: =Inputs!B18 -> 0.075 | C30: =IFERROR(B30/$B$36,0) -> 0.12096774 | D30: =$D$37*C30 -> 1.0368664 | E30: =D30*$B$11 -> 51976.037
A31: Sick Leave | B31: =Inputs!B19 -> 0.0125 | C31: =IFERROR(B31/$B$36,0) -> 0.02016129 | D31: =$D$37*C31 -> 0.17281106 | E31: =D31*$B$11 -> 8662.6728
A32: Recruiting / Hiring | B32: =Inputs!B22 -> 0.015 | C32: =IFERROR(B32/$B$36,0) -> 0.024193548 | D32: =$D$37*C32 -> 0.20737327 | E32: =D32*$B$11 -> 10395.207
A33: Training / Certification | B33: =Inputs!B23 -> 0.015 | C33: =IFERROR(B33/$B$36,0) -> 0.024193548 | D33: =$D$37*C33 -> 0.20737327 | E33: =D33*$B$11 -> 10395.207
A34: Administrative / HR / Payroll | B34: =Inputs!B34 -> 0.03 | C34: =IFERROR(B34/$B$36,0) -> 0.048387097 | D34: =$D$37*C34 -> 0.41474654 | E34: =D34*$B$11 -> 20790.415
A35: Insurance / Misc. | B35: =Inputs!B30+Inputs!B31 -> 0.0225 | C35: =IFERROR(B35/$B$36,0) -> 0.036290323 | D35: =$D$37*C35 -> 0.31105991 | E35: =D35*$B$11 -> 15592.811
A36: Total raw weight | B36: =SUM(B24:B35) -> 0.62
A37: Total burden dollars to allocate | D37: =B5-B4 -> 8.5714286 | E37: =D37*$B$11 -> 429668.57
A38: Allocated burden check | D38: =SUM(D24:D35) -> 8.5714286 | E38: =SUM(E24:E35) -> 429668.57
A39: Difference (should be 0) | D39: =D37-D38 -> 0 | E39: =E37-E38 -> 0
A40: Important | B40: If labor is 70% of total cost, the burden add-on equals 30% of total cost, which is 42.857% of direct labor.

Sheet Overhead_GA
A1: GASQ Overhead, G&A, and Profit
A2: GASQ-branded operating model worksheet
A3: Line Item | B3: Input / Formula | C3: Hourly Amount | D3: Annual Amount
A4: Administrative / HR / Payroll | B4: =Direct_Labor!$C$8*Inputs!B34 -> 0.73434 | C4: =B4 -> 0.73434 | D4: =C4*Scope_of_Work!$B$14 -> 36810.996
A5: Accounting / Legal | B5: =Direct_Labor!$C$8*Inputs!B35 -> 0.48956 | C5: =B5 -> 0.48956 | D5: =C5*Scope_of_Work!$B$14 -> 24540.664
A6: Corporate Overhead | B6: =Direct_Labor!$C$8*Inputs!B36 -> 2.93736 | C6: =B6 -> 2.93736 | D6: =C6*Scope_of_Work!$B$14 -> 147243.98
A7: G&A | B7: =Direct_Labor!$C$8*Inputs!B37 -> 1.46868 | C7: =B7 -> 1.46868 | D7: =C7*Scope_of_Work!$B$14 -> 73621.991
A8: Profit / Fee | B8: =Direct_Labor!$C$8*Inputs!B38 -> 1.95824 | C8: =B8 -> 1.95824 | D8: =C8*Scope_of_Work!$B$14 -> 98162.655
A9: Total Overhead / G&A / Profit | C9: =SUM(C4:C8) -> 7.58818 | D9: =SUM(D4:D8) -> 380380.29

Sheet Vendor_Pricing
A1: GASQ Vendor Pricing Guardrails
A2: Rates benchmarked to GASQ government TCO, vendor TCO, floor, and target guardrails.
A3: Pricing Model
A4: Government TCO per Productive Coverage Hour | B4: =Government_TCO!B8 -> 73.469388
A5: Vendor TCO Rate (= Government TCO x Vendor TCO Factor) | B5: =B4*Inputs!B39 -> 51.428571
A6: Vendor Absorbed Floor Rate (= Vendor TCO x Floor Factor) | B6: =B5*Inputs!B40 -> 36
A7: Vendor Target Rate | B7: =B6+((B5-B6)/2) -> 43.714286
A8: Vendor Ceiling Rate (= Vendor TCO) | B8: =B5 -> 51.428571
A9: Capital Recovery Saved per Hour | B9: =B4-B5 -> 22.040816
A10: Annual Capital Recovery Saved | B10: =B9*Scope_of_Work!B14 -> 1104862
A11: Minimum Weekly Hours for Floor Eligibility | B11: =Inputs!B41 -> 1500
A12: Blended Actual Bill Rate from Post_Positions | B12: =IF(IFERROR(Post_Positions!$U$5,0)>0,Post_Positions!$U$15,"") -> 51.428571 | D12: Feed Status | E12: =IF(Post_Positions!$U$5>0,"Linked","Manual") -> Linked
A13: Vendor Evaluation Inputs
A14: Vendor | B14: Bid Rate | C14: Vendor Weekly Hours Billed | D14: Floor Eligible? | E14: Range Position | F14: Initial Interpretation
A15: Vendor 1 | B15: 35 | C15: 1500 | D15: =IF(C15="","",IF(C15>=B11,"Yes","No")) -> Yes | E15: =IF(B15="","",IF(B15<B6,"Below Floor",IF(B15<B7,"Between Floor and Target",IF(B15<=B8,"Between Target and Ceiling","Above Ceiling")))) -> Below Floor | F15: =IF(B15="","",IF(B15<B6,"Unrealistic / high performance risk",IF(B15<B7,"Aggressive pricing",IF(B15<=B8,"Competitive and reasonable","Potentially overpriced")))) -> Unrealistic / high performance risk
A16: Vendor 2 | B16: 37 | C16: 900 | D16: =IF(C16="","",IF(C16>=B11,"Yes","No")) -> No | E16: =IF(B16="","",IF(B16<B6,"Below Floor",IF(B16<B7,"Between Floor and Target",IF(B16<=B8,"Between Target and Ceiling","Above Ceiling")))) -> Between Floor and Target | F16: =IF(B16="","",IF(B16<B6,"Unrealistic / high performance risk",IF(B16<B7,"Aggressive pricing",IF(B16<=B8,"Competitive and reasonable","Potentially overpriced")))) -> Aggressive pricing
A17: Vendor 3 | B17: 41 | C17: 2000 | D17: =IF(C17="","",IF(C17>=B11,"Yes","No")) -> Yes | E17: =IF(B17="","",IF(B17<B6,"Below Floor",IF(B17<B7,"Between Floor and Target",IF(B17<=B8,"Between Target and Ceiling","Above Ceiling")))) -> Between Floor and Target | F17: =IF(B17="","",IF(B17<B6,"Unrealistic / high performance risk",IF(B17<B7,"Aggressive pricing",IF(B17<=B8,"Competitive and reasonable","Potentially overpriced")))) -> Aggressive pricing
A18: Vendor 4 | B18: 42 | C18: 800 | D18: =IF(C18="","",IF(C18>=B11,"Yes","No")) -> No | E18: =IF(B18="","",IF(B18<B6,"Below Floor",IF(B18<B7,"Between Floor and Target",IF(B18<=B8,"Between Target and Ceiling","Above Ceiling")))) -> Between Floor and Target | F18: =IF(B18="","",IF(B18<B6,"Unrealistic / high performance risk",IF(B18<B7,"Aggressive pricing",IF(B18<=B8,"Competitive and reasonable","Potentially overpriced")))) -> Aggressive pricing
A19: Vendor 5 | B19: 50 | C19: 1600 | D19: =IF(C19="","",IF(C19>=B11,"Yes","No")) -> Yes | E19: =IF(B19="","",IF(B19<B6,"Below Floor",IF(B19<B7,"Between Floor and Target",IF(B19<=B8,"Between Target and Ceiling","Above Ceiling")))) -> Between Target and Ceiling | F19: =IF(B19="","",IF(B19<B6,"Unrealistic / high performance risk",IF(B19<B7,"Aggressive pricing",IF(B19<=B8,"Competitive and reasonable","Potentially overpriced")))) -> Competitive and reasonable

Sheet Price_Realism
A1: GASQ Price Realism Review
A2: GASQ-branded operating model worksheet
A3: Benchmark Rates
A4: Government TCO Benchmark | B4: =Government_TCO!B8 -> 73.469388
A5: Vendor Absorbed Floor | B5: =Vendor_Pricing!B6 -> 36
A6: Vendor Target Rate | B6: =Vendor_Pricing!B7 -> 43.714286
A7: Vendor Ceiling Rate | B7: =Vendor_Pricing!B8 -> 51.428571
A9: Evaluation Grid
A10: Vendor | B10: Bid Rate | C10: Delta vs Gov TCO | D10: Delta % | E10: Benchmark Position | F10: Recommendation
A11: =Vendor_Pricing!A15 -> Vendor 1 | B11: =Vendor_Pricing!B15 -> 35 | C11: =IF(B11="","",B11-$B$4) -> -38.469388 | D11: =IFERROR(C11/$B$4,"") -> -0.52361111 | E11: =Vendor_Pricing!E15 -> Below Floor
A12: =Vendor_Pricing!A16 -> Vendor 2 | B12: =Vendor_Pricing!B16 -> 37 | C12: =IF(B12="","",B12-$B$4) -> -36.469388 | D12: =IFERROR(C12/$B$4,"") -> -0.49638889 | E12: =Vendor_Pricing!E16 -> Between Floor and Target
A13: =Vendor_Pricing!A17 -> Vendor 3 | B13: =Vendor_Pricing!B17 -> 41 | C13: =IF(B13="","",B13-$B$4) -> -32.469388 | D13: =IFERROR(C13/$B$4,"") -> -0.44194444 | E13: =Vendor_Pricing!E17 -> Between Floor and Target
A14: =Vendor_Pricing!A18 -> Vendor 4 | B14: =Vendor_Pricing!B18 -> 42 | C14: =IF(B14="","",B14-$B$4) -> -31.469388 | D14: =IFERROR(C14/$B$4,"") -> -0.42833333 | E14: =Vendor_Pricing!E18 -> Between Floor and Target
A15: =Vendor_Pricing!A19 -> Vendor 5 | B15: =Vendor_Pricing!B19 -> 50 | C15: =IF(B15="","",B15-$B$4) -> -23.469388 | D15: =IFERROR(C15/$B$4,"") -> -0.31944444 | E15: =Vendor_Pricing!E19 -> Between Target and Ceiling
A18: Typical Federal-Style Logic | B18: Below floor suggests performance risk. Bids within target/ceiling range are generally the most defensible.

Sheet Buyer_Vendor_Comparison
A1: GASQ Buyer vs Vendor Price Comparison
A2: GASQ-branded operating model worksheet
A3: Core Pricing Comparison
A4: Metric | B4: Buyer / Government | C4: Vendor TCO | D4: Vendor Target | E4: Vendor Floor
A5: Annual Coverage Hours | B5: =Scope_of_Work!B14 -> 50128 | C5: =Scope_of_Work!B14 -> 50128 | D5: =Scope_of_Work!B14 -> 50128 | E5: =Scope_of_Work!B14 -> 50128
A6: FTEs Required | B6: =Scope_of_Work!B15 -> 34.428571 | C6: =Scope_of_Work!B15 -> 34.428571 | D6: =Scope_of_Work!B15 -> 34.428571 | E6: =Scope_of_Work!B15 -> 34.428571
A7: Rate per Productive Coverage Hour | B7: =Government_TCO!B8 -> 73.469388 | C7: =Vendor_Pricing!B5 -> 51.428571 | D7: =Vendor_Pricing!B7 -> 43.714286 | E7: =Vendor_Pricing!B6 -> 36
A8: Annual Total Cost | B8: =B5*B7 -> 3682873.5 | C8: =C5*C7 -> 2578011.4 | D8: =D5*D7 -> 2191309.7 | E8: =E5*E7 -> 1804608
A9: Hourly Savings vs Buyer | B9: - | C9: =B7-C7 -> 22.040816 | D9: =B7-D7 -> 29.755102 | E9: =B7-E7 -> 37.469388
A10: Annual Capital Recovery Saved | B10: - | C10: =B8-C8 -> 1104862 | D10: =B8-D8 -> 1491563.8 | E10: =B8-E8 -> 1878265.5
A11: Savings % vs Buyer | B11: - | C11: =IFERROR((B8-C8)/B8,0) -> 0.3 | D11: =IFERROR((B8-D8)/B8,0) -> 0.405 | E11: =IFERROR((B8-E8)/B8,0) -> 0.51
A13: Capital Recovery Highlight
A14: Comparison Point | B14: Formula Output
A15: Buyer Government TCO Rate | B15: =Government_TCO!B8 -> 73.469388
A16: Vendor TCO Rate | B16: =Vendor_Pricing!B5 -> 51.428571
A17: Capital Recovery Saved per Hour | B17: =Vendor_Pricing!B9 -> 22.040816
A18: Annual Capital Recovery Saved | B18: =Vendor_Pricing!B10 -> 1104862
A19: Capital Recovery Savings % | B19: =IFERROR(B18/(B15*Scope_of_Work!B14),0) -> 0.3
A21: Buyer-to-Vendor Cost Comparison
A22: Buyer annual in-house/government-equivalent cost | B22: =Government_TCO!B12 -> 3682873.5
A23: Vendor annual cost at TCO rate | B23: =Vendor_Pricing!B5*Scope_of_Work!B14 -> 2578011.4
A24: Vendor annual cost at target rate | B24: =Vendor_Pricing!B7*Scope_of_Work!B14 -> 2191309.7
A25: Vendor annual cost at floor rate | B25: =Vendor_Pricing!B6*Scope_of_Work!B14 -> 1804608
A26: Best annual capital recovery using vendor floor | B26: =B22-B25 -> 1878265.5
A29: This worksheet provides a side-by-side price comparison between the buyer's government-style TCO and vendor pricing, including capital recovery saved.

Sheet Summary
A1: GASQ Executive Summary
A2: GASQ brand refresh | TCO + Capital Recovery model | formulas reviewed and corrected
A3: Key Outputs
A4: Annual Coverage Hours | B4: =Scope_of_Work!B14 -> 50128
A5: FTEs Required | B5: =Scope_of_Work!B15 -> 34.428571
A6: Government /Customer TCO per Hour | B6: =Government_TCO!B8 -> 73.469388
A7: Annual Total Cost of Ownership | B7: =Government_TCO!B12 -> 3682873.5
A8: Annual Uniform & Equipment Cost | B8: =Uniform_Equipment!C35 -> 43322.125
A9: Vendor TCO Rate | B9: =Vendor_Pricing!B5 -> 51.428571
A10: Vendor Floor Rate | B10: =Vendor_Pricing!B6 -> 36
A11: Vendor Target Rate | B11: =Vendor_Pricing!B7 -> 43.714286
A12: Vendor Ceiling Rate | B12: =Vendor_Pricing!B8 -> 51.428571
A13: Capital Recovery per Hour | B13: =Vendor_Pricing!B9 -> 22.040816
A14: Annual Capital Recovery | B14: =Vendor_Pricing!B10 -> 1104862
A15: Annual Vehicle Cost | B15: =Vehicle!C29 -> 122466.33
A16: Annual Capital Recovery Saved (Vendor TCO) | B16: =Buyer_Vendor_Comparison!C10 -> 1104862
A18: Model Checks & Cross-References
A19: Annual Uniform & Equipment Cost | B19: =Uniform_Equipment!C35 -> 43322.125
A20: Buyer vs Vendor Comparison
A21: Vendor TCO Annual Savings | B21: =Buyer_Vendor_Comparison!C10 -> 1104862
A22: Vendor Target Annual Savings | B22: =Buyer_Vendor_Comparison!D10 -> 1491563.8
A23: Vendor Floor Annual Savings | B23: =Buyer_Vendor_Comparison!E10 -> 1878265.5
A24: Burden Build | B24: =Government_TCO!D37 -> 8.5714286
A25: Burden Check | B25: =Government_TCO!D39 -> 0

Sheet Contract_Summary
B1: GASQ Workforce-to-Post™ Capital Recovery Contract Summary
B2: Executive contract summary with TCO, pricing guardrails, and capital recovery outputs | J2: =IF(IFERROR(Post_Positions!$U$5,0)>0,Post_Positions!$U$5,Scope_of_Work!B13) -> 964
B3: CONFIDENTIAL | J3: =IF(IFERROR(Post_Positions!$U$5,0)>0,Post_Positions!$U$15,Vendor_Pricing!B7) -> 51.428571
J4: =IF(IFERROR(Post_Positions!$U$5,0)>0,Post_Positions!$U$14,Direct_Labor!C8) -> 20
J5: =Direct_Labor!C5 -> 3.48
J6: =Direct_Labor!C7 -> 0.846
B7: Contract Economics | J7: =Direct_Labor!C8+Fringe_Costs!C12 -> 36.39228
B8: Weekly Hours | F8: =J2 -> 964 | J8: =IF(IFERROR(Post_Positions!$U$5,0)>0,Post_Positions!$U$7,J2*J3) -> 49577.143
B9: Weekly Billings (excluding holiday billings) | F9: =J8 -> 49577.143 | J9: =J8*52 -> 2578011.4
B10: Blended Straight Time Pay Rate | F10: =J4 -> 20 | J10: =IF(IFERROR(Post_Positions!$U$5,0)>0,Post_Positions!$U$17+Post_Positions!$U$18,Direct_Labor!D8+Fringe_Costs!D12+Operations!D14) -> 1002560
B11: Blended Straight Time Bill Rate | F11: =J3 -> 51.428571 | J11: =Vehicle!C29 -> 122466.33
B12: Overtime Bill Rate | F12: =J20 -> 77.142857 | J12: =Vehicle!C29 -> 122466.33
B13: Holiday Bill Rate | F13: =J21 -> 77.142857 | J13: =J9+J11 -> 2700477.8
B14: Effective Pay Rate | F14: =J7 -> 36.39228 | J14: =J10+J12 -> 1125026.3
B15: Effective Bill Rate | F15: =J22 -> 53.871644 | J15: =J13-J14 -> 1575451.4
B16: Effective Direct Labor Ratio | F16: =J18 -> 0.70762767 | J16: =IFERROR(J15/J13,0) -> 0.5833973
B17: Effective Markup | F17: =J19 -> 1.4131726 | J17: =IFERROR(J15/Scope_of_Work!B14,0) -> 31.428571
J18: =IFERROR(J7/J3,0) -> 0.70762767
B19: Revenue & Cost Summary | J19: =IFERROR(J3/J7,0) -> 1.4131726
B20: Total Annual Revenue (from hourly billings) * | F20: =J9 -> 2578011.4 | J20: =J3*1.5 -> 77.142857
B21: Vehicle and Other Pass Through Billings | F21: =J11 -> 122466.33 | J21: =J3*1.5 -> 77.142857
B22: Total Annual Contract Revenue * | F22: =J13 -> 2700477.8 | J22: =IFERROR(J13/Scope_of_Work!B14,0) -> 53.871644
J23: =Government_TCO!B8 -> 73.469388
B24: Direct Expense | F24: =J10 -> 1002560 | J24: =Vendor_Pricing!B5 -> 51.428571
B25: Vehicle and Other Pass Through Costs | F25: =J12 -> 122466.33 | J25: =Vendor_Pricing!B6 -> 36
B26: Total Annual Costs * | F26: =J14 -> 1125026.3 | J26: =Vendor_Pricing!B7 -> 43.714286
J27: =Vendor_Pricing!B8 -> 51.428571
B28: Contributory Profit | F28: =J15 -> 1575451.4 | J28: =Vendor_Pricing!B9 -> 22.040816
B29: Profit as a % of Revenue | F29: =J16 -> 0.5833973 | J29: =Vendor_Pricing!B10 -> 1104862
B30: Contributory Profit Per Hour | F30: =J17 -> 31.428571 | J30: =Buyer_Vendor_Comparison!C11 -> 0.3
B31: Working Capital Requirement | F31: =J12 -> 122466.33 | J31: =IFERROR(J14/12,0) -> 93752.194
B32: Payback & Recovery Period (months) | F32: =J36 -> 3.6 | J32: =IF(J2>=J31,"Eligible","Not Eligible") -> Not Eligible
J33: =IFERROR((J26-J25)/(J27-J25),0) -> 0.5
B34: GASQ Capital Recovery | J34: =IF(J29>=100000,"A",IF(J29>=50000,"B",IF(J29>=25000,"C",IF(J29>0,"D","F")))) -> A
B35: Buyer Government TCO Rate | F35: =J23 -> 73.469388 | J35: =IFERROR(J23*J2*52/12,0) -> 306906.12
B36: Vendor True Cost of Ownership Rate | F36: =J24 -> 51.428571 | J36: =IFERROR(J29/J35,0) -> 3.6
B37: Vendor Absorbed Floor Rate | F37: =J25 -> 36
B38: Vendor Target Rate | F38: =J26 -> 43.714286
B39: Vendor Ceiling Rate | F39: =J27 -> 51.428571
B40: Capital Recovery Saved per Hour | F40: =J28 -> 22.040816
...

Sheet Appraisal_Full_Scope_Report
B1: GASQ Workforce-to-Post™ Capital Recovery Appraisal Full Scope Report
B2: Workforce Total Cost of Ownership (TCO) -vs- Vendor Outsourced Security Services
B3: Prepared for: Jessie Gibbs - TACTICAL ELITE PROTECTIVE SERVICE | G3: =TODAY( ) -> 46100
B5: Appraisal Comparison Summary
B6: DESCRIPTION | F6: TOTAL BUYER WORKFORCE COST OF OWNERSHIP | H6: TOTAL VENDOR OUTSOURCED COST OF OWNERSHIP | J6: DIFFERENCE SAVED
B7: Workforce Baseline Assumption Labor Rate | F7: =Inputs!$B$4 -> 20 | H7: =Inputs!$B$4 -> 20 | J7: =""
B8: Workforce Hourly Cost Per Security Professional | F8: =Government_TCO!$B$8 -> 73.469388 | H8: =Vendor_Pricing!$B$5 -> 51.428571 | J8: =F8-H8 -> 22.040816
B9: Overtime/Holiday Rate | F9: =F8*1.5 -> 110.20408 | H9: =H8*1.5 -> 77.142857 | J9: =F9-H9 -> 33.061224
B10: Workforce Annual Cost per Security Professional | F10: =F8*Inputs!$B$5 -> 106971.43 | H10: =H8*Inputs!$B$5 -> 74880 | J10: =F10-H10 -> 32091.429
B11: Total Weekly Hours of Coverage | F11: =Scope_of_Work!$B$13 -> 964 | H11: =F11 -> 964 | J11: =""
B12: Total Monthly Hours of Coverage | F12: =ROUND(Scope_of_Work!$B$14/12,0) -> 4177 | H12: =F12 -> 4177 | J12: =""
B13: Total Annual Hours of Coverage | F13: =Scope_of_Work!$B$14 -> 50128 | H13: =F13 -> 50128 | J13: =""
B14: Total Weeks of Coverage | F14: =Scope_of_Work!$B$6 -> 52 | H14: =F14 -> 52 | J14: =""
B15: Total Months of Coverage | F15: =ROUND(F14/4.3333333333,0) -> 12 | H15: =F15 -> 12 | J15: =""
B16: Total Workforce Required for Coverage | F16: =Scope_of_Work!$B$15 -> 34.428571 | H16: =F16 -> 34.428571 | J16: =""
B17: Total Weekly Cost | F17: =F11*F8 -> 70824.49 | H17: =H11*H8 -> 49577.143 | J17: =F17-H17 -> 21247.347
B18: Total Monthly Cost | F18: =F12*F8 -> 306881.63 | H18: =H12*H8 -> 214817.14 | J18: =F18-H18 -> 92064.49
B19: Total Annual Cost | F19: =Government_TCO!$B$12 -> 3682873.5 | H19: =Scope_of_Work!$B$14*Vendor_Pricing!$B$5 -> 2578011.4 | J19: =F19-H19 -> 1104862
B20: Operational Capital Recovered | F20: ="" | H20: =J19 -> 1104862 | J20: =""
B21: Operational Capital Recovered (%) | F21: ="" | H21: =IFERROR(H20/F19,0) -> 0.3 | J21: =""
B22: Payback & Recovery Period | F22: ="" | H22: =IFERROR(H19/(F19/12),0) -> 8.4 | J22: =""
B24: Coverage Statement
B25: All price calculations include the full cost of workforce staffing and support services, including but not limited to: livable base wages, employer-paid payroll taxes (FICA, FUTA, SUTA), workers’ compensation, general liability insurance, unemployment insurance, paid time off, healthcare and fringe benefits, uniforms and equipment, onboarding and training, site supervision, quality assurance oversight, management and administrative support, 24/7 dispatch capability, compliance with local, state, and federal labor laws, and all service-level guarantees (including open post protection, vendor replacement, and price lock guarantees) unless otherwise specified.
B28: "CFO Tested. CFO Approved"
B29: (470) 633-2816 | info@getasecurityquote.com | getasecurityquotenow.com
B30: Key Components of the GetASecurityQuote Security Capital Recovery Report
B31: Direct Labor Costs
B32: • Wages: Hourly pay for each guard (based on market, union scale, or livable wage rates)
B33: • Overtime: If scheduling exceeds 40 hours/week per guard or during holidays
B34: • Paid Non-Worked Hours: Includes holidays, sick leave, vacation, training
B35: Mandatory Payroll Burden
B36: • Employer Taxes: FICA, FUTA, SUTA, Medicare
B37: • Workers’ Compensation Insurance: Risk-rated by job classification (high for security)
... B68: Notes:

Sheet Training_Module
A1: Training Description | B1: Hours | C1: Training Wage | D1: Training Cost Per Hour | E1: Employees Trained | F1: Instructor Cost | G1: Equipment Cost | H1: Certification Fee | I1: Travel Cost | J1: Total Training Cost
A2: CPR / First Aid / AED | B2: 8 | C2: 21 | D2: =C2/0.7 -> 30 | E2: =IFERROR(ROUNDUP(Post_Positions!$E$22/28,0),"") -> 35 | F2: 200 | G2: 600 | H2: 0 | I2: 0 | J2: =B2*D2*E2+F2+G2+H2+I2 -> 9200
A3: Pre‑Assignment Training | B3: 16 | C3: 21 | D3: =C3/0.7 -> 30 | E3: =IFERROR(ROUNDUP(Post_Positions!$E$22/28,0),"") -> 35 | F3: 0 | G3: 0 | H3: 0 | I3: 0 | J3: =B3*D3*E3+F3+G3+H3+I3 -> 16800
A4: Field Training | B4: 40 | C4: 21 | D4: =C4/0.7 -> 30 | E4: =IFERROR(ROUNDUP(Post_Positions!$E$22/28,0),"") -> 35 | F4: 0 | G4: 0 | H4: 0 | I4: 0 | J4: =B4*D4*E4+F4+G4+H4+I4 -> 42000
A5: Weapons Training | B5: 8 | C5: 21 | D5: =C5/0.7 -> 30 | E5: =IFERROR(ROUNDUP(Post_Positions!$E$22/28,0),"") -> 35 | F5: 0 | G5: 0 | H5: 0 | I5: 0 | J5: =B5*D5*E5+F5+G5+H5+I5 -> 8400
A6: Site Specific Training | B6: 8 | C6: 21 | D6: =C6/0.7 -> 30 | E6: =IFERROR(ROUNDUP(Post_Positions!$E$22/28,0),"") -> 35 | F6: 0 | G6: 0 | H6: 0 | I6: 0 | J6: =B6*D6*E6+F6+G6+H6+I6 -> 8400
A7: Supervisor Training | B7: 12 | C7: 25 | D7: =C7/0.7 -> 35.714286 | E7: =IFERROR(ROUNDUP(Post_Positions!$E$22/28,0),"") -> 35 | F7: 0 | G7: 0 | H7: 0 | I7: 0 | J7: =B7*D7*E7+F7+G7+H7+I7 -> 15000
A8: Annual Refresher | B8: 8 | C8: 21 | D8: =C8/0.7 -> 30 | E8: =IFERROR(ROUNDUP(Post_Positions!$E$22/28,0),"") -> 35 | F8: 0 | G8: 0 | H8: 0 | I8: 0 | J8: =B8*D8*E8+F8+G8+H8+I8 -> 8400
I9: Total Training Cost | J9: =SUM(J2:J8) -> 108200

Sheet Equipment_Uniform_Module
A1: Item | B1: Cost Per Unit | C1: Quantity | D1: Replacement Cycle (Years) | E1: Annualized Cost
A2: Uniform | B2: 250 | C2: 25 | D2: 1 | E2: =B2*C2/D2 -> 6250
A3: Radio | B3: 600 | C3: 25 | D3: 3 | E3: =B3*C3/D3 -> 5000
A4: Body Armor | B4: 800 | C4: 10 | D4: 5 | E4: =B4*C4/D4 -> 1600
A5: Flashlight | B5: 75 | C5: 25 | D5: 2 | E5: =B5*C5/D5 -> 937.5
A6: Duty Belt | B6: 150 | C6: 25 | D6: 3 | E6: =B6*C6/D6 -> 1250
D7: Total Annual Equipment Cost | E7: =SUM(E2:E6) -> 15037.5

Sheet Workforce_Maintenance_Module
A1: Category | B1: Days/Hours | C1: Employees | D1: Cost Per Hour | E1: Total Cost
A2: Vacation Days | B2: 80 | C2: 25 | D2: 21 | E2: =B2*C2*D2 -> 42000
A3: Sick Days | B3: 40 | C3: 25 | D3: 21 | E3: =B3*C3*D3 -> 21000
A4: Holiday Pay | B4: 80 | C4: 25 | D4: 21 | E4: =B4*C4*D4 -> 42000
A5: Turnover Replacement | B5: 40 | C5: 10 | D5: 21 | E5: =B5*C5*D5 -> 8400
A6: Recruiting / Hiring | B6: 20 | C6: 10 | D6: 21 | E6: =B6*C6*D6 -> 4200
D7: Total Workforce Maintenance Cost | E7: =SUM(E2:E6) -> 117600

Sheet Government_IGCE_Model
A1: Cost Category | B1: Input | C1: Formula / Notes
A2: Direct Labor Rate | B2: 21 | C2: User Input
A3: Burden Build Up | B3: =IFERROR(B2/Inputs!$B$42,0) -> 30 | C3: =B2/0.7 -> 30
A4: Workforce Maintenance Cost | B4: =Workforce_Maintenance_Module!E7 -> 117600 | C4: Linked from Workforce_Maintenance_Module
A5: Training Cost | B5: =Training_Module!J9 -> 108200 | C5: Linked from Training_Module
A6: Equipment Cost | B6: =Equipment_Uniform_Module!E7 -> 15037.5 | C6: Linked from Equipment_Uniform_Module
A7: Total Estimated Cost | B7: =SUM(B3:B6) -> 240867.5 | C7: =SUM(B3:B6) -> 240867.5

Sheet Workforce_to_Post
A1: GASQ Workforce-to-Post™ Calculator
A2: Calculates productive coverage, workforce basis, unavailable hours, and relief factor from the active post roster.
A4: Weekly Coverage Hours | B4: =IF(Post_Positions!U5="",Scope_of_Work!B13,Post_Positions!U5) -> 964 | D4: Interpretation
A5: Annual Coverage Hours | B5: =B4*52 -> 50128 | D5: Coverage hours entered by roster or scope.
A6: Standard Paid Hours per FTE | B6: =2080 -> 2080 | D6: Coverage hours multiplied by 52 weeks.
A7: Relief Factor (Workforce Basis ÷ Productive Basis) | B7: =Inputs!B43/B6 -> 1.8 | D7: Paid hours per FTE basis used by vendor model.
A8: Productive FTEs Required | B8: =IFERROR(B5/B6,0) -> 24.1 | D8: Shows productivity loss between coverage and workforce basis.
A9: Paid Workforce FTEs Required | B9: =B8*B7 -> 43.38 | D9: Bare-minimum productive staffing requirement.
A10: Government Workforce Hours Basis | B10: =Inputs!B43 -> 3744 | D10: Paid headcount needed to support relief.
A11: Unavailable Hours per FTE | B11: =B10-B6 -> 1664 | D11: Government-style workforce basis used in model.
A12: Unavailable Hours Workforce Cost Basis | B12: =B9*B11 -> 72184.32 | D12: Hours paid but not worked per FTE.
A13: Blended Pay Rate | B13: =IF(Post_Positions!U5>0,Post_Positions!U14,Direct_Labor!C8) -> 20 | D13: Total unavailable paid hours across the workforce.
A14: Unavailable Hours Workforce Cost | B14: =B12*B13 -> 1443686.4 | D14: Active weighted pay rate from roster.
A15: Training Cost Annual | B15: =Training_Module!J9 -> 108200 | D15: Dollar cost of unavailable paid hours.
A16: Equipment / Uniform Annual | B16: =Equipment_Uniform_Module!E7 -> 15037.5
A17: Workforce Maintenance Annual | B17: =Workforce_Maintenance_Module!E7 -> 117600
A18: Total Hidden Workforce Cost | B18: =SUM(B14:B17) -> 1684523.9

Sheet Capital_Recovery_Dashboard
A1: GASQ Capital Recovery Dashboard
A2: Single-page dashboard for Security Cost Rating, Capital Recovery Receipt, Vendor Price Evaluation, and IGCE comparison.
A4: KPI | B4: Value | D4: Security Cost Rating | G4: Vendor Price Evaluation
A5: Annual Coverage Hours | B5: =Workforce_to_Post!B5 -> 50128 | D5: Actual Rate Position | E5: =IF(B8="","No Rate",IF(B8<Vendor_Pricing!B6,"Below Floor",IF(B8<Vendor_Pricing!B7,"Floor to Target",IF(B8<=Vendor_Pricing!B8,"Target to Ceiling","Above Ceiling")))) -> Target to Ceiling | G5: Scenario | H5: Rate | I5: Interpretation
A6: Government TCO / Hr | B6: =Government_TCO!B8 -> 73.469388 | D6: SCRS Grade | E6: =IF(E5="Below Floor","D",IF(E5="Floor to Target","A",IF(E5="Target to Ceiling","B",IF(E5="Above Ceiling","C","NR")))) -> B | G6: Below Floor | H6: =Vendor_Pricing!B6-0.01 -> 35.99 | I6: Unrealistic / high risk
A7: Vendor TCO / Hr | B7: =Vendor_Pricing!B5 -> 51.428571 | D7: Recommendation | E7: =IF(E5="Below Floor","High performance risk / underbid",IF(E5="Floor to Target","Best value zone",IF(E5="Target to Ceiling","Acceptable with justification",IF(E5="Above Ceiling","Premium / likely overpriced","Review inputs")))) -> Acceptable with justification | G7: Floor to Target | H7: =AVERAGE(Vendor_Pricing!B6,Vendor_Pricing!B7) -> 39.857143 | I7: Best value
A8: Actual Bill Rate / Hr | B8: =IF(Post_Positions!U5>0,Post_Positions!U15,Vendor_Pricing!B7) -> 51.428571 | G8: Target to Ceiling | H8: =AVERAGE(Vendor_Pricing!B7,Vendor_Pricing!B8) -> 47.571429 | I8: Acceptable
A9: Annual Government Cost | B9: =Government_TCO!B12 -> 3682873.5 | D9: Comparison | G9: Above Ceiling | H9: =Vendor_Pricing!B8+0.01 -> 51.438571 | I9: Likely overpriced
A10: Annual Actual Vendor Cost | B10: =IFERROR(B8*B5,0) -> 2578011.4 | D10: IGCE Total Estimated Cost | E10: =Government_IGCE_Model!B7 -> 240867.5 | G10: Actual Blended Rate | H10: =IF(Post_Positions!U5>0,Post_Positions!U15,Vendor_Pricing!B7) -> 51.428571 | I10: =E7 -> Acceptable with justification
A11: Annual Capital Recovered | B11: =B9-B10 -> 1104862 | D11: Training Annual | E11: =Training_Module!J9 -> 108200
A12: Capital Recovery % | B12: =IFERROR(B11/B9,0) -> 0.3 | D12: Workforce Maintenance Annual | E12: =Workforce_Maintenance_Module!E7 -> 117600
D13: Equipment Annual | E13: =Equipment_Uniform_Module!E7 -> 15037.5
D14: Hidden Workforce Cost Total | E14: =Workforce_to_Post!B18 -> 1684523.9

Sheet Security_Cost_Rating_Report
A1: GASQ Security Cost Rating Report™
A2: Automated grading of the active roster rate against floor, target, and ceiling guardrails.
A4: Government TCO Benchmark | B4: =Government_TCO!B8 -> 73.469388 | D4: Government-style TCO per productive hour.
A5: Vendor Absorbed Floor | B5: =Vendor_Pricing!B6 -> 36 | D5: Minimum sustainable absorbed floor.
A6: Vendor Target | B6: =Vendor_Pricing!B7 -> 43.714286 | D6: Preferred best-value band midpoint.
A7: Vendor Ceiling | B7: =Vendor_Pricing!B8 -> 51.428571 | D7: Upper sustainable range benchmark.
A8: Actual Blended Bill Rate | B8: =IF(Post_Positions!U5>0,Post_Positions!U15,Vendor_Pricing!B7) -> 51.428571 | D8: Current blended rate from roster if active.
A9: Delta vs Gov TCO | B9: =B8-B4 -> -22.040816
A10: Delta vs Target | B10: =B8-B6 -> 7.7142857
A11: Security Cost Position | B11: =IF(B8<B5,"Below Floor",IF(B8<B6,"Floor to Target",IF(B8<=B7,"Target to Ceiling","Above Ceiling"))) -> Target to Ceiling | D11: Used for grade logic.
A12: SCRS Grade | B12: =IF(B11="Below Floor","D",IF(B11="Floor to Target","A",IF(B11="Target to Ceiling","B","C"))) -> B | D12: A = best value; D = high risk underbid.
A13: Executive Recommendation | B13: =IF(B12="A","Strong pricing alignment",IF(B12="B","Acceptable but monitor margin",IF(B12="C","Premium pricing; justify scope or quality","Underpriced; performance risk"))) -> Acceptable but monitor margin
A14: Annual Capital Recovery Saved | B14: =MAX(0,(B4-B8)*Workforce_to_Post!B5) -> 1104862
A15: Capital Recovery % | B15: =IFERROR(B14/(B4*Workforce_to_Post!B5),0) -> 0.3

Sheet Capital_Recovery_Receipt
A1: GASQ Capital Recovery Receipt™
A2: Point-of-sale style summary of annual and hourly economics for buyer-facing review.
A4: Line Item | B4: Government View | C4: Vendor / GASQ View | E4: Receipt Notes
A5: Coverage Hours (Annual) | B5: =Workforce_to_Post!B5 -> 50128 | C5: =Workforce_to_Post!B5 -> 50128 | E5: Shows the government benchmark and GASQ alternative side by side.
A6: Hourly Rate | B6: =Government_TCO!B8 -> 73.469388 | C6: =IF(Post_Positions!U5>0,Post_Positions!U15,Vendor_Pricing!B7) -> 51.428571 | E6: Vendor/GASQ view uses active blended roster rate when available.
A7: Annual Cost | B7: =B5*B6 -> 3682873.5 | C7: =C5*C6 -> 2578011.4 | E7: All-in annual view includes recurring training, maintenance, and equipment.
A8: Training Annual | B8: =Training_Module!J9 -> 108200 | C8: =Training_Module!J9 -> 108200 | E8: Capital recovered = benchmark all-in annual cost less GASQ all-in annual cost.
A9: Workforce Maintenance Annual | B9: =Workforce_Maintenance_Module!E7 -> 117600 | C9: =Workforce_Maintenance_Module!E7 -> 117600 | E9: Use this sheet as the buyer-safe summary.
A10: Equipment / Uniform Annual | B10: =Equipment_Uniform_Module!E7 -> 15037.5 | C10: =Equipment_Uniform_Module!E7 -> 15037.5
A11: All-In Annual View | B11: =SUM(B7:B10) -> 3923711 | C11: =SUM(C7:C10) -> 2818848.9
A12: Capital Recovered ($) | C12: =B11-C11 -> 1104862
A13: Capital Recovered (%) | C13: =IFERROR(C12/B11,0) -> 0.28158599

Sheet Vendor_Price_Evaluation
A1: GASQ Vendor Price Evaluation
A2: Evaluates sample and actual rates against the floor, target, and ceiling bands.
A4: Vendor / Scenario | B4: Bid Rate | C4: Delta vs Gov TCO | D4: Delta % | E4: Band | F4: Recommendation | G4: Annual Cost
A5: Absorbed Floor | B5: =Vendor_Pricing!B6 -> 36 | C5: =B5-Government_TCO!B8 -> -37.469388 | D5: =IFERROR(C5/Government_TCO!B8,0) -> -0.51 | E5: =IF(B5<Vendor_Pricing!B6,"Below Floor",IF(B5<Vendor_Pricing!B7,"Floor to Target",IF(B5<=Vendor_Pricing!B8,"Target to Ceiling","Above Ceiling"))) -> Floor to Target | F5: =IF(E5="Below Floor","High risk underbid",IF(E5="Floor to Target","Best value",IF(E5="Target to Ceiling","Acceptable","Overpriced"))) -> Best value | G5: =B5*Workforce_to_Post!B5 -> 1804608
A6: Target | B6: =Vendor_Pricing!B7 -> 43.714286 | C6: =B6-Government_TCO!B8 -> -29.755102 | D6: =IFERROR(C6/Government_TCO!B8,0) -> -0.405 | E6: =IF(B6<Vendor_Pricing!B6,"Below Floor",IF(B6<Vendor_Pricing!B7,"Floor to Target",IF(B6<=Vendor_Pricing!B8,"Target to Ceiling","Above Ceiling"))) -> Target to Ceiling | F6: =IF(E6="Below Floor","High risk underbid",IF(E6="Floor to Target","Best value",IF(E6="Target to Ceiling","Acceptable","Overpriced"))) -> Acceptable | G6: =B6*Workforce_to_Post!B5 -> 2191309.7
A7: Ceiling | B7: =Vendor_Pricing!B8 -> 51.428571 | C7: =B7-Government_TCO!B8 -> -22.040816 | D7: =IFERROR(C7/Government_TCO!B8,0) -> -0.3 | E7: =IF(B7<Vendor_Pricing!B6,"Below Floor",IF(B7<Vendor_Pricing!B7,"Floor to Target",IF(B7<=Vendor_Pricing!B8,"Target to Ceiling","Above Ceiling"))) -> Target to Ceiling | F7: =IF(E7="Below Floor","High risk underbid",IF(E7="Floor to Target","Best value",IF(E7="Target to Ceiling","Acceptable","Overpriced"))) -> Acceptable | G7: =B7*Workforce_to_Post!B5 -> 2578011.4
A8: Actual Blended Rate | B8: =IF(Post_Positions!U5>0,Post_Positions!U15,Vendor_Pricing!B7) -> 51.428571 | C8: =B8-Government_TCO!B8 -> -22.040816 | D8: =IFERROR(C8/Government_TCO!B8,0) -> -0.3 | E8: =IF(B8<Vendor_Pricing!B6,"Below Floor",IF(B8<Vendor_Pricing!B7,"Floor to Target",IF(B8<=Vendor_Pricing!B8,"Target to Ceiling","Above Ceiling"))) -> Target to Ceiling | F8: =IF(E8="Below Floor","High risk underbid",IF(E8="Floor to Target","Best value",IF(E8="Target to Ceiling","Acceptable","Overpriced"))) -> Acceptable | G8: =B8*Workforce_to_Post!B5 -> 2578011.4

Sheet Government_IGCE_Comparison
A1: GASQ Government IGCE Comparison
A2: Compares the government-style estimate to the active GASQ roster-driven model.
A4: Cost Component | B4: Government IGCE | C4: GASQ Active Model | D4: Variance | E4: Variance % | F4: Notes
