Workbook

Sheet Start_Here
A1: GASQ Workforce-to-Post™ Model
A2: Enter data only in highlighted cells. All formulas, dashboards, and client-facing reports are protected.
A4: Recommended workflow | D4: Editing rules | G4: Live model KPIs
A5: 1. Inputs | B5: Open Inputs | D5: Editable input cells | E5: Type only in highlighted cells | G5: Annual Coverage Hours | H5: =Appraisal_Full_Scope_Report!F15 -> 17472
A6: 2. Post roster | B6: Open Post_Positions | D6: Locked formula/report cells | E6: Protected | G6: Service Requster TCO / Hr | H6: =Appraisal_Full_Scope_Report!F8 -> 129.97639
A7: 3. Vendor pricing | B7: Open Vendor_Pricing | D7: Protection password | E7: GASQ | G7: Vendor TCO / Hr | H7: =Appraisal_Full_Scope_Report!H8 -> 90.983473
A8: 4. CLIN pricing | B8: Open CLIN Pricing | G8: Annual Capital Recovery | H8: =Appraisal_Full_Scope_Report!H20 -> 681284.25
A9: 5. Contract summary | B9: Open Contract_Summary
A10: 6. Dashboards | B10: Open GASQ_Dashboard | G10: Visible user tabs
A11: 7. Reports | B11: Open Appraisal Report | G11: • Inputs
A12: 8. Buyer report | B12: Open Buyer_Executive_Report | G12: • Post_Positions
A13: 9. Automation guide | B13: Open Automation_Guide | G13: • Vehicle
G14: • Uniform_Equipment
A15: Buyer PDF shortcut | G15: • Training_Module
A16: OPEN BUYER REPORT TAB (click here) | E16: OPEN AUTOMATION GUIDE (click here)
A19: PDF export reminder | G19: • Vendor_Pricing
A20: The buyer PDF is exported from the Buyer_Executive_Report tab. In Excel: File → Export / Save As → PDF. For a Windows one-click exporter, use the included Export_Buyer_Report.vbs script in the same folder as this workbook.
G23: • Capital_Recovery_Receipt
G24: • Vendor_Price_Evaluation
G25: • Government_IGCE_Comparison
G26: • Capital_Recovery_Dashboard
G27: • GASQ_Dashboard
G28: • Direct_Labor
G29: • Fringe_Costs

Sheet Buyer_Executive_Report
A1: GASQ Buyer Executive Report
A2: Automated buyer-facing summary linked live to Direct_Labor, Summary, Appraisal_Full_Scope_Report, and Vendor_Pricing. Update inputs, recalculate, and export this sheet to PDF.
F3: Setup one-click export
A4: Executive KPIs
A5: Annual Coverage Hours | B5: =Summary!$B$4 -> 17472 | C5: FTEs Required | D5: =Summary!$B$5 -> 12 | E5: Service Requester TCO / Hr | F5: =Summary!$B$6 -> 129.97639 | G5: Annual Service Requester TCO | H5: =Summary!$B$7 -> 2270947.5
A7: Vendor TCO / Hr | B7: =Summary!$B$9 -> 90.983473 | C7: Vendor BAFO / Hr | D7: =Summary!$B$11 -> 77.335952 | E7: Capital Recovery Opportunity ($/Hr) | F7: =Summary!$B$13 -> 38.992917 | G7: Annual Service Requester Savings ($/Year) | H7: =Summary!$B$16 -> 681284.25
A8: Payback Period (Months) | B8: =Appraisal_Full_Scope_Report!$H$22 -> 8.4
A10: Direct Labor Cost Stack
A11: Component | B11: Annual Cost | C11: % of Vendor Stack | D11: Notes
A12: Direct Labor | B12: =Direct_Labor!$D$11 -> 732597.47 | C12: =IFERROR(B12/$B$16,0) -> 0.48242356 | D12: Core productive labor
A13: Fringe & Burden | B13: =Direct_Labor!$D$25 -> 150548.78 | C13: =IFERROR(B13/$B$16,0) -> 0.099138042 | D13: Payroll taxes and paid time off
A14: Operations & Support | B14: =Direct_Labor!$D$40 -> 169734.22 | C14: =IFERROR(B14/$B$16,0) -> 0.11177186 | D14: Training, equipment, vehicles, and insurance
A15: Overhead / G&A / Profit | B15: =Direct_Labor!$D$50 -> 465696.82 | C15: =IFERROR(B15/$B$16,0) -> 0.30666653 | D15: Corporate overhead, G&A, and profit
A16: Total Vendor Labor Stack | B16: =Direct_Labor!$D$52 -> 1518577.3 | C16: =IFERROR(B16/$B$16,0) -> 1 | D16: Vendor fully burdened labor cost stack
A19: Buyer vs Vendor Scenario Comparison
A20: Metric | B20: Buyer / Gov | C20: Vendor TCO | D20: Vendor BAFO/LPTA Target | E20: Vendor LPTA
A21: Annual Coverage Hours | B21: =Summary!$B$4 -> 17472 | C21: =Summary!$B$4 -> 17472 | D21: =Summary!$B$4 -> 17472 | E21: =Summary!$B$4 -> 17472
A22: Rate / Productive Hour | B22: =Summary!$B$6 -> 129.97639 | C22: =Summary!$B$9 -> 90.983473 | D22: =Summary!$B$11 -> 77.335952 | E22: =Summary!$B$10 -> 63.688431
A23: Annual Total Cost | B23: =Summary!$B$7 -> 2270947.5 | C23: =Appraisal_Full_Scope_Report!$H$19 -> 1589663.2 | D23: =D21*D22 -> 1351213.8 | E23: =E21*E22 -> 1112764.3
A24: Hourly Savings vs Buyer | B24: =0 -> 0 | C24: =B22-C22 -> 38.992917 | D24: =B22-D22 -> 52.640438 | E24: =B22-E22 -> 66.287959
A25: Annual Savings / Capital Recovery | B25: =0 -> 0 | C25: =B23-C23 -> 681284.25 | D25: =B23-D23 -> 919733.73 | E25: =B23-E23 -> 1158183.2
A26: Savings % vs Buyer | B26: =0 -> 0 | C26: =IFERROR(C25/B23,0) -> 0.3 | D26: =IFERROR(D25/B23,0) -> 0.405 | E26: =IFERROR(E25/B23,0) -> 0.51
A28: Auto-Generated Buyer Takeaways
A29: ="Direct labor represents "&IFERROR(TEXT(C12,"0.0%"),"-")&" of the vendor fully burdened labor stack." -> Direct labor represents 48.2% of the vendor fully burdened labor stack.
A30: ="Vendor TCO pricing lowers annual buyer spend by "&IFERROR(TEXT(H7,"$#,##0"),"-")&" per year compared with the buyer should-cost benchmark." -> Vendor TCO pricing lowers annual buyer spend by $681,284 per year compared with the buyer should-cost benchmark.
A31: ="Capital recovery opportunity equals "&IFERROR(TEXT(F7,"$0.00"),"-")&" per hour and "&IFERROR(TEXT(H7,"$#,##0"),"-")&" per year." -> Capital recovery opportunity equals $38.99 per hour and $681,284 per year.
A32: ="The buyer should-cost benchmark is "&IFERROR(TEXT(F5,"$0.00"),"-")&" per productive hour versus vendor TCO of "&IFERROR(TEXT(B7,"$0.00"),"-")&"." -> The buyer should-cost benchmark is $129.98 per productive hour versus vendor TCO of $90.98.
A34: This report updates automatically from the linked model tabs. Recalculate in Excel before exporting if you change inputs.

Sheet Automation_Guide
A1: Automation Guide
A2: This workbook includes a buyer report tab plus ready-to-use export scripts. Use the workbook on desktop Excel for best results.
A4: Step | B4: Action | C4: Details
A5: 1 | B5: Open the workbook | C5: Use desktop Excel. The Buyer_Executive_Report tab is moved near the front and colored burgundy.
A6: 2 | B6: Update inputs | C6: Edit the blue / designated input cells on Inputs, Post_Positions, Vendor_Pricing, and related modules.
A7: 3 | B7: Review the report | C7: Open Buyer_Executive_Report and confirm KPIs, cost stack, and comparison values.
A8: 4 | B8: Manual PDF export | C8: In Excel: File → Export / Save As → PDF. Export only Buyer_Executive_Report.
A9: 5 | B9: Windows one-click export | C9: Put Export_Buyer_Report.vbs in the same folder as this workbook, then double-click the script. It recalculates and exports the PDF automatically.
A10: 6 | B10: Optional in-workbook macro button | C10: Import Export_Buyer_Report.bas into VBA, insert a shape/button, and assign macro ExportBuyerReport.
A12: VBA macro (copy/import the included .bas file)
A13: Sub ExportBuyerReport() | C13: Application.CalculateFull
A14: Dim ws As Worksheet, pdfPath As String, folderPath As String | C14: ws.ExportAsFixedFormat Type:=xlTypePDF, Filename:=pdfPath, Quality:=xlQualityStandard, IncludeDocProperties:=True, IgnorePrintAreas:=False, OpenAfterPublish:=True
A15: Set ws = ThisWorkbook.Worksheets("Buyer_Executive_Report") | C15: End Sub
A16: folderPath = ThisWorkbook.Path
A17: If Len(folderPath) = 0 Then folderPath = Application.DefaultFilePath
A18: pdfPath = folderPath & Application.PathSeparator & "GASQ_Buyer_Executive_Report_" & Format(Now, "yyyymmdd_hhmm") & ".pdf"
A19: Export assignment steps
A20: 1 | B20: Open VBA editor | C20: Press Alt+F11 in Excel.
A21: 2 | B21: Import module | C21: File → Import File… → select Export_Buyer_Report.bas.
A22: 3 | B22: Add button/shape | C22: On Buyer_Executive_Report insert a shape and label it Generate Buyer PDF.
A23: 4 | B23: Assign macro | C23: Right-click shape → Assign Macro… → ExportBuyerReport.
A24: 5 | B24: Use it | C24: Click the shape to export the current buyer report to PDF in the workbook folder.

Sheet Inputs
A1: GASQ Assumptions & Controls
A2: GASQ-branded operating model worksheet
A3: Core Controls
A4: Direct Labor Wage ($/paid hour) | B4: 27.48 | C4: =Direct_Labor!C4 -> 33.74 | E4: Edit highlighted assumptions only
A5: Annual Paid Hours per FTE | B5: 1456
A6: Annual Productive Coverage Hours per FTE | B6: 1456
A7: Locality Pay % | B7: 0 | C7: =Direct_Labor!C5 -> 0
A8: Shift Differential % | B8: 0 | C8: =Direct_Labor!C8 -> 0
A9: OT/Holiday Premium % | B9: 0.08 | C9: =Direct_Labor!C9 -> 2.6992
A10: Labor Market Adjustment % | B10: 0 | C10: =Direct_Labor!C6 -> 0
A11: H&W Cash ($/paid hour) | B11: 4.22 | C11: =Direct_Labor!C7 -> 4.22
A12: Fringe / Employer Burden
A13: FICA / Medicare % | B13: 0.0765 | C13: =Direct_Labor!C17 -> 3.2076297
A14: FUTA % | B14: 0.006 | C14: =Direct_Labor!C18 -> 0.2515788
A15: SUTA % | B15: 0.02 | C15: =Direct_Labor!C19 -> 0.838596
A16: Workers Compensation % | B16: 0.016 | C16: =Direct_Labor!C20 -> 0.6708768
A17: Health & Welfare ($/paid hour) | B17: 0 | C17: =Direct_Labor!C21 -> 0
A18: Vacation % | B18: 0.02 | C18: =Direct_Labor!C22 -> 0.838596
A19: Paid Holidays % | B19: 0.04 | C19: =Direct_Labor!C23 -> 1.677192
A20: Sick Leave % | B20: 0.027 | C20: =Direct_Labor!C24 -> 1.1321046
A21: DON/DOFF Minutes per 8-Hour Shift | B21: 15 | C21: =Direct_Labor!C10 -> 1.2706 | E21: Enter minutes per shift (e.g., 15); model converts minutes ÷ 480 into an hourly premium.
A22: Operations / Support
A23: Recruiting / Hiring % | B23: 0 | C23: =Direct_Labor!$C$30 -> 0
A24: Training / Certification % | B24: 0.015 | C24: =Direct_Labor!$C$31 -> 0.628947
A25: Uniforms / Equipment % | B25: 0.001 | C25: =Direct_Labor!$C$32 -> 1.1071394
A26: Field Supervision % | B26: 0 | C26: =Direct_Labor!$C$33 -> 0
A27: Contract Management % | B27: 0 | C27: =Direct_Labor!$C$34 -> 0
A28: Quality Assurance % | B28: 0 | C28: =Direct_Labor!$C$35 -> 0
A29: Vehicles / Patrol % | B29: 0.02 | C29: =Direct_Labor!$C$36 -> 3.5046454
A30: Technology / Systems % | B30: 0.01 | C30: =Direct_Labor!$C$37 -> 0.419298
A31: General Liability Insurance % | B31: 0.0892 | C31: =Direct_Labor!$C$38 -> 3.7401382
A32: Umbrella / Other Insurance % | B32: 0.0075 | C32: =Direct_Labor!$C$39 -> 0.3144735
A34: Corporate & Pricing Controls
A35: Administrative / HR / Payroll % | B35: 0 | C35: =Direct_Labor!$C$45 -> 0
A36: Accounting / Legal % | B36: 0 | C36: =Direct_Labor!$C$46 -> 0
A37: Corporate Overhead (10%) | B37: 0.1 | C37: =Direct_Labor!$C$47 -> 4.19298
A38: G&A (8%) | B38: 0.08 | C38: =Direct_Labor!$C$48 -> 3.354384
A39: Profit / Fee % (5% - 8%) | B39: 0.21 | C39: =Direct_Labor!$C$49 -> 19.106529
A40: Vendor TCO Factor vs Government TCO | B40: 0.7 | C40: =Vendor_Pricing!B5 -> 90.983473
A41: Vendor Floor Factor vs Vendor TCO | B41: 0.7 | C41: =Vendor_Pricing!B6 -> 63.688431
...

Sheet CFO_Bill_Rate_Breakdown
A1: CFO Bill Rate Breakdown
A2: Consolidated line-by-line build of the GASQ should-cost model with hourly and annual amounts.
A3: Description | B3: Hourly Amount | C3: Annual Amount
A4: Direct Labor
A5: =Direct_Labor!A4 -> Base Consolidated Blended Direct Labor Wage | B5: =Direct_Labor!C4 -> 33.74 | C5: =Direct_Labor!D4 -> 589505.28
A6: =Direct_Labor!A5 -> Locality Pay | B6: =Direct_Labor!C5 -> 0 | C6: =Direct_Labor!D5 -> 0
A7: =Direct_Labor!A6 -> Labor Market Adjustment | B7: =Direct_Labor!C6 -> 0 | C7: =Direct_Labor!D6 -> 0
A8: =Direct_Labor!A7 -> H&W (Cash) | B8: =Direct_Labor!C7 -> 4.22 | C8: =Direct_Labor!D7 -> 73731.84
A9: =Direct_Labor!A8 -> Shift Differential | B9: =Direct_Labor!C8 -> 0 | C9: =Direct_Labor!D8 -> 0
A10: =Direct_Labor!A9 -> OT/Holiday Premium | B10: =Direct_Labor!C9 -> 2.6992 | C10: =Direct_Labor!D9 -> 47160.422
A11: =Direct_Labor!A10 -> DON/DOFF | B11: =Direct_Labor!C10 -> 1.2706 | C11: =Direct_Labor!D10 -> 22199.923
A12: =Direct_Labor!A11 -> Total Direct Labor | B12: =Direct_Labor!C11 -> 41.9298 | C12: =Direct_Labor!D11 -> 732597.47
A14: Fringe / Employer Burden
A15: =Direct_Labor!A17 -> FICA / Medicare | B15: =Direct_Labor!C17 -> 3.2076297 | C15: =Direct_Labor!D17 -> 56043.706
A16: =Direct_Labor!A18 -> FUTA | B16: =Direct_Labor!C18 -> 0.2515788 | C16: =Direct_Labor!D18 -> 4395.5848
A17: =Direct_Labor!A19 -> SUTA | B17: =Direct_Labor!C19 -> 0.838596 | C17: =Direct_Labor!D19 -> 14651.949
A18: =Direct_Labor!A20 -> Workers Compensation | B18: =Direct_Labor!C20 -> 0.6708768 | C18: =Direct_Labor!D20 -> 11721.559
A19: =Direct_Labor!A21 -> Health & Welfare | B19: =Direct_Labor!C21 -> 0 | C19: =Direct_Labor!D21 -> 0
A20: =Direct_Labor!A22 -> Vacation | B20: =Direct_Labor!C22 -> 0.838596 | C20: =Direct_Labor!D22 -> 14651.949
A21: =Direct_Labor!A23 -> Paid Holidays | B21: =Direct_Labor!C23 -> 1.677192 | C21: =Direct_Labor!D23 -> 29303.899
A22: =Direct_Labor!A24 -> Sick Leave | B22: =Direct_Labor!C24 -> 1.1321046 | C22: =Direct_Labor!D24 -> 19780.132
A23: =Direct_Labor!A25 -> Total Fringe / Burden | B23: =Direct_Labor!C25 -> 8.6165739 | C23: =Direct_Labor!D25 -> 150548.78
A24: =Direct_Labor!A26 -> Total Direct Labor + Fringe | B24: =Direct_Labor!C26 -> 50.546374 | C24: =Direct_Labor!D26 -> 883146.24
A26: Operations / Support
A27: =Direct_Labor!$A$30 -> Recruiting / Hiring | B27: =Direct_Labor!$C$30 -> 0 | C27: =Direct_Labor!$D$30 -> 0
A28: =Direct_Labor!$A$31 -> Training / Certification | B28: =Direct_Labor!$C$31 -> 0.628947 | C28: =Direct_Labor!$D$31 -> 10988.962
A29: =Direct_Labor!$A$32 -> Uniforms / Equipment | B29: =Direct_Labor!$C$32 -> 1.1071394 | C29: =Direct_Labor!$D$32 -> 19343.94
A30: =Direct_Labor!$A$33 -> Field Supervision | B30: =Direct_Labor!$C$33 -> 0 | C30: =Direct_Labor!$D$33 -> 0
A31: =Direct_Labor!$A$34 -> Contract Management | B31: =Direct_Labor!$C$34 -> 0 | C31: =Direct_Labor!$D$34 -> 0
A32: =Direct_Labor!$A$35 -> Quality Assurance | B32: =Direct_Labor!$C$35 -> 0 | C32: =Direct_Labor!$D$35 -> 0
A33: =Direct_Labor!$A$36 -> Vehicles / Patrol | B33: =Direct_Labor!$C$36 -> 3.5046454 | C33: =Direct_Labor!$D$36 -> 61233.164
A34: =Direct_Labor!$A$37 -> Technology / Systems | B34: =Direct_Labor!$C$37 -> 0.419298 | C34: =Direct_Labor!$D$37 -> 7325.9747
A35: =Direct_Labor!$A$38 -> General Liability Insurance | B35: =Direct_Labor!$C$38 -> 3.7401382 | C35: =Direct_Labor!$D$38 -> 65347.694
A36: =Direct_Labor!$A$39 -> Umbrella / Other Insurance | B36: =Direct_Labor!$C$39 -> 0.3144735 | C36: =Direct_Labor!$D$39 -> 5494.481
A37: =Direct_Labor!$A$40 -> Total Operations / Support | B37: =Direct_Labor!$C$40 -> 9.7146414 | C37: =Direct_Labor!$D$40 -> 169734.22
A39: Overhead / G&A / Profit
A40: =Direct_Labor!$A$45 -> Administrative / HR / Payroll | B40: =Direct_Labor!$C$45 -> 0 | C40: =Direct_Labor!$D$45 -> 0
A41: =Direct_Labor!$A$46 -> Accounting / Legal | B41: =Direct_Labor!$C$46 -> 0 | C41: =Direct_Labor!$D$46 -> 0
A42: =Direct_Labor!$A$47 -> Corporate Overhead | B42: =Direct_Labor!$C$47 -> 4.19298 | C42: =Direct_Labor!$D$47 -> 73259.747
A43: =Direct_Labor!$A$48 -> G&A | B43: =Direct_Labor!$C$48 -> 3.354384 | C43: =Direct_Labor!$D$48 -> 58607.797
...

Sheet Post_Positions
A1: POST POSITION SUMMARY | B1: Qty Required | C1: Blended Pay Rate | D1: Weekly Hours/Hits | E1: Weekly Cost | F1: Monthly Hours | G1: Monthly Cost | H1: Annual Hours/Hits | I1: Annual Direct Labor Cost | K1: INPUT / CONTROL PANEL | L1: User Pay Rate | M1: Weekly Cost | N1: Monthly Cost | O1: Annual Cost | P1: Staff Count | Q1: Weekly Hours | R1: Monthly Hours | S1: Annual Hours
A2: Unarmed S/O | B2: =+P2 -> 6 | C2: =+L2 -> 27.48 | D2: =+Q2 -> 168 | E2: =+M2 -> 4616.64 | F2: =+R2 -> 728 | G2: =+N2 -> 20005.44 | H2: =+S2 -> 8736 | I2: =+O2 -> 240065.28 | K2: Post / Labor Category | L2: 27.48 | M2: =+$L2*$Q2 -> 4616.64 | N2: =+$L2*$R2 -> 20005.44 | O2: =+$L2*$S2 -> 240065.28 | P2: =+Q2/28 -> 6 | Q2: =+S2/52 -> 168 | R2: =+S2/12 -> 728 | S2: 8736
A3: Supervisor | B3: =+P3 -> 6.2686567 | C3: =+L3 -> 40 | D3: =+Q3 -> 168 | E3: =+M3 -> 6720 | F3: =+R3 -> 728 | G3: =+N3 -> 29120 | H3: =+S3 -> 8736 | I3: =+O3 -> 349440 | K3: Set pay rate | L3: 40 | M3: =+$L3*$Q3 -> 6720 | N3: =+$L3*$R3 -> 29120 | O3: =+$L3*$S3 -> 349440 | P3: =+Q3/26.8 -> 6.2686567 | Q3: =+S3/52 -> 168 | R3: =+S3/12 -> 728 | S3: 8736
A4: Unarmed S/O | B4: =+P4 -> 0 | C4: =+L4 -> 0 | D4: =+Q4 -> 0 | E4: =+M4 -> 0 | F4: =+R4 -> 0 | G4: =+N4 -> 0 | H4: =+S4 -> 0 | I4: =+O4 -> 0 | K4: Auto weekly cost | L4: 0 | M4: =+$L4*$Q4 -> 0 | N4: =+$L4*$R4 -> 0 | O4: =+$L4*$S4 -> 0 | P4: =+Q4/26.8 -> 0 | Q4: =+S4/52 -> 0 | R4: =+S4/12 -> 0 | S4: 0
A5: Unarmed S/O | B5: =+P5 -> 0 | C5: =+L5 -> 0 | D5: =+Q5 -> 0 | E5: =+M5 -> 0 | F5: =+R5 -> 0 | G5: =+N5 -> 0 | H5: =+S5 -> 0 | I5: =+O5 -> 0 | K5: Auto monthly cost | L5: 0 | M5: =+$L5*$Q5 -> 0 | N5: =+$L5*$R5 -> 0 | O5: =+$L5*$S5 -> 0 | P5: =+Q5/26.8 -> 0 | Q5: =+S5/52 -> 0 | R5: =+S5/12 -> 0 | S5: 0
A6: Rovering Patrol Officer | B6: =+P6 -> 0 | C6: =+L6 -> 0 | D6: =+Q6 -> 0 | E6: =+M6 -> 0 | F6: =+R6 -> 0 | G6: =+N6 -> 0 | H6: =+S6 -> 0 | I6: =+O6 -> 0 | K6: Auto annual cost | L6: 0 | M6: =+$L6*$Q6 -> 0 | N6: =+$L6*$R6 -> 0 | O6: =+$L6*$S6 -> 0 | P6: =+Q6/26.8 -> 0 | Q6: =+S6/52 -> 0 | R6: =+S6/12 -> 0 | S6: 0
A7: Unarmed S/O | B7: =+P7 -> 0 | C7: =+L7 -> 0 | D7: =+Q7 -> 0 | E7: =+M7 -> 0 | F7: =+R7 -> 0 | G7: =+N7 -> 0 | H7: =+S7 -> 0 | I7: =+O7 -> 0 | K7: Auto staff count | L7: 0 | M7: =+$L7*$Q7 -> 0 | N7: =+$L7*$R7 -> 0 | O7: =+$L7*$S7 -> 0 | P7: =+Q7/26.8 -> 0 | Q7: =+S7/52 -> 0 | R7: =+S7/12 -> 0 | S7: 0
A8: Unarmed S/O | B8: =+P8 -> 0 | C8: =+L8 -> 0 | D8: =+Q8 -> 0 | E8: =+M8 -> 0 | F8: =+R8 -> 0 | G8: =+N8 -> 0 | H8: =+S8 -> 0 | I8: =+O8 -> 0 | K8: Input weekly hours | L8: 0 | M8: =+$L8*$Q8 -> 0 | N8: =+$L8*$R8 -> 0 | O8: =+$L8*$S8 -> 0 | P8: =+Q8/26.8 -> 0 | Q8: =+S8/52 -> 0 | R8: =+S8/12 -> 0 | S8: 0
A9: Unarmed S/O | B9: =+P9 -> 0 | C9: =+L9 -> 0 | D9: =+Q9 -> 0 | E9: =+M9 -> 0 | F9: =+R9 -> 0 | G9: =+N9 -> 0 | H9: =+S9 -> 0 | I9: =+O9 -> 0 | K9: Auto monthly hours | L9: 0 | M9: =+$L9*$Q9 -> 0 | N9: =+$L9*$R9 -> 0 | O9: =+$L9*$S9 -> 0 | P9: =+Q9/26.8 -> 0 | Q9: =+S9/52 -> 0 | R9: =+S9/12 -> 0 | S9: 0
A10: Unarmed S/O | B10: =+P10 -> 0 | C10: =+L10 -> 0 | D10: =+Q10 -> 0 | E10: =+M10 -> 0 | F10: =+R10 -> 0 | G10: =+N10 -> 0 | H10: =+S10 -> 0 | I10: =+O10 -> 0 | K10: Input annual hours | L10: 0 | M10: =+$L10*$Q10 -> 0 | N10: =+$L10*$R10 -> 0 | O10: =+$L10*$S10 -> 0 | P10: =+Q10/26.8 -> 0 | Q10: =+S10/52 -> 0 | R10: =+S10/12 -> 0 | S10: 0
A11: Unarmed S/O | B11: =+P11 -> 0 | C11: =+L11 -> 0 | D11: =+Q11 -> 0 | E11: =+M11 -> 0 | F11: =+R11 -> 0 | G11: =+N11 -> 0 | H11: =+S11 -> 0 | I11: =+O11 -> 0 | L11: 0 | M11: =+$L11*$Q11 -> 0 | N11: =+$L11*$R11 -> 0 | O11: =+$L11*$S11 -> 0 | P11: =+Q11/26.8 -> 0 | Q11: =+S11/52 -> 0 | R11: =+S11/12 -> 0 | S11: 0
A12: ESTIMATED TOTAL | B12: =SUM(B2:B11) -> 12.268657 | C12: =AVERAGEIF(C2:C11,">0") -> 33.74 | D12: =SUM(D2:D11) -> 336 | E12: =SUM(E2:E11) -> 11336.64 | F12: =SUM(F2:F11) -> 1456 | G12: =SUM(G2:G11) -> 49125.44 | H12: =SUM(H2:H11) -> 17472 | I12: =SUM(I2:I11) -> 589505.28 | K12: Control Totals | M12: =SUM(M2:M11) -> 11336.64 | N12: =SUM(N2:N11) -> 49125.44 | O12: =SUM(O2:O11) -> 589505.28 | P12: =+Q12/26.8 -> 12.537313 | Q12: =+S12/52 -> 336 | R12: =SUM(R2:R11) -> 1456 | S12: =SUM(S2:S11) -> 17472

Sheet Uniform_Equipment
A1: GASQ Uniform & Equipment Module
A2: GASQ-branded operating model worksheet
A3: Program Inputs
A4: Input / Line Item | B4: Value | C4: Units | D4: Calc / Annualized | E4: Notes
A5: FTEs Required | B5: =ROUNDUP(_Calc_Backend!$X$38,0) -> 12 | C5: FTEs | E5: Linked from Scope_of_Work
A6: Annual Labor Hours | B6: =_Calc_Backend!$X$37 -> 17472 | C6: hours | E6: Linked from Scope_of_Work
A7: Uniform Sets per Employee | B7: 3 | C7: sets/FTE | E7: Hardcoded input
A8: Cost per Uniform Set | B8: 333 | C8: $ / set | E8: Hardcoded input
A9: Uniform Useful Life | B9: 12 | C9: months | E9: Annual issue if 12 months
A10: Duty Gear Kit per Employee | B10: 350 | C10: $ / FTE | E10: Belts, pouches, accessories
A11: Duty Gear Useful Life | B11: 24 | C11: months | E11: Annualized over useful life
A12: Radio / Device per Employee | B12: 275 | C12: $ / FTE | E12: Phones, radios, chargers
A13: Radio / Device Useful Life | B13: 36 | C13: months | E13: Annualized over useful life
A14: Badge / ID / Misc. Issue per Employee | B14: 45 | C14: $ / FTE | E14: Initial issue
A15: Badge / ID Useful Life | B15: 12 | C15: months | E15: Annualized over useful life
A16: Annual Consumables / Small Equipment | B16: 85 | C16: $ / FTE / year | E16: Gloves, batteries, notebooks
A17: Spare / Float Inventory Factor | B17: 0.1 | C17: % | E17: Reserve for extras, turnover
A18: Program Management / Logistics Factor | B18: 0.05 | C18: % | E18: Sizing and replacement admin
A21: Annual Cost Build
A22: Metric | B22: Formula | C22: Result | D22: Units | E22: Comment
A23: Initial Uniform Issue | B23: =B5*B7*B8 -> 11988 | C23: =B23 -> 11988 | D23: $ | E23: FTEs × sets × cost
A24: Annual Uniform Cost | B24: =IFERROR(C23*(12/B9),0) -> 11988 | C24: =B24 -> 11988 | D24: $ / year | E24: Annualized by useful life
A25: Initial Duty Gear Issue | B25: =B5*B10 -> 4200 | C25: =B25 -> 4200 | D25: $ | E25: FTEs × kit cost
A26: Annual Duty Gear Cost | B26: =IFERROR(C25*(12/B11),0) -> 2100 | C26: =B26 -> 2100 | D26: $ / year | E26: Annualized by useful life
A27: Initial Radio / Device Issue | B27: =B5*B12 -> 3300 | C27: =B27 -> 3300 | D27: $ | E27: FTEs × device cost
A28: Annual Radio / Device Cost | B28: =IFERROR(C27*(12/B13),0) -> 1100 | C28: =B28 -> 1100 | D28: $ / year | E28: Annualized by useful life
A29: Initial Badge / ID / Misc. Issue | B29: =B5*B14 -> 540 | C29: =B29 -> 540 | D29: $ | E29: FTEs × issue cost
A30: Annual Badge / ID / Misc. Cost | B30: =IFERROR(C29*(12/B15),0) -> 540 | C30: =B30 -> 540 | D30: $ / year | E30: Annualized by useful life
A31: Annual Consumables | B31: =B5*B16 -> 1020 | C31: =B31 -> 1020 | D31: $ / year | E31: Direct annual cost
A32: Subtotal Annual Equipment Cost | B32: =SUM(C24,C26,C28,C30,C31) -> 16748 | C32: =B32 -> 16748 | D32: $ / year | E32: Before reserve and logistics
A33: Spare / Float Inventory Cost | B33: =C32*B17 -> 1674.8 | C33: =B33 -> 1674.8 | D33: $ / year | E33: Reserve factor
A34: Program Management / Logistics | B34: =SUM(C32:C33)*B18 -> 921.14 | C34: =B34 -> 921.14 | D34: $ / year | E34: Sizing, shipping, admin
A35: Total Annual Uniform & Equipment Cost | B35: =SUM(C32:C34) -> 19343.94 | C35: =B35 -> 19343.94 | D35: $ / year | E35: Feeds Operations tab
A36: Uniform & Equipment Cost per Labor Hour | B36: =IFERROR(C35/B6,0) -> 1.1071394 | C36: =B36 -> 1.1071394 | D36: $ / labor hour | E36: Feeds Operations hourly rate
A39: Module Checks
A40: Check | B40: Formula | C40: Result | D40: Status
A41: FTE link populated | B41: =IF(B5>0,"OK","CHECK") -> OK | C41: =B41 -> OK | D41: Scope link
A42: Annual labor hours populated | B42: =IF(B6>0,"OK","CHECK") -> OK | C42: =B42 -> OK | D42: Scope link
A43: Hourly cost available | B43: =IF(C36>=0,"OK","CHECK") -> OK | C43: =B43 -> OK | D43: Operations feed
A46: This replacement module annualizes uniforms, duty gear, devices, ID issue, and consumables, then converts the total into a cost per labor hour for the Operations tab.

Sheet Vehicle
A1: GASQ Vehicle / Patrol Cost Model
A2: GASQ-branded operating model worksheet
A3: Vehicle Assumptions
A4: Line Item | B4: Input / Formula | C4: Units | D4: Notes
A5: Vehicles Required | B5: 1 | C5: vehicles | D5: User input
A6: Average Miles per Vehicle per Day | B6: 365 | C6: miles/day | D6: User input
A7: Operating Days per Week | B7: 7 | C7: days/week | D7: User input
A8: Weeks of Coverage | B8: 52 | C8: weeks/year | D8: User input
A9: Fuel Economy | B9: 22 | C9: mpg | D9: User input
A10: Fuel Cost per Gallon | B10: 4 | C10: $/gallon | D10: User input
A11: Maintenance Cost per Mile | B11: 0.18 | C11: $/mile | D11: User input
A12: Monthly Lease / Payment per Vehicle | B12: 850 | C12: $/month | D12: User input
A13: Monthly Insurance per Vehicle | B13: 225 | C13: $/month | D13: User input
A14: Monthly GPS / Telematics per Vehicle | B14: 1 | C14: $/month | D14: User input
A15: Annual Registration / Tags per Vehicle | B15: 250 | C15: $/year | D15: User input
A18: Vehicle Cost Calculations
A19: Metric | B19: Formula | C19: Result | D19: Units
A20: Daily Fleet Miles | B20: =B5*B6 -> 365 | C20: =B20 -> 365 | D20: miles/day
A21: Annual Fleet Miles | B21: =C20*B7*B8 -> 132860 | C21: =B21 -> 132860 | D21: miles/year
A22: Annual Fuel Gallons | B22: =IFERROR(C21/B9,0) -> 6039.0909 | C22: =B22 -> 6039.0909 | D22: gallons/year
A23: Annual Fuel Cost | B23: =C22*B10 -> 24156.364 | C23: =B23 -> 24156.364 | D23: $/year
A24: Annual Maintenance Cost | B24: =C21*B11 -> 23914.8 | C24: =B24 -> 23914.8 | D24: $/year
A25: Annual Lease / Payment Cost | B25: =B5*B12*12 -> 10200 | C25: =B25 -> 10200 | D25: $/year
A26: Annual Insurance Cost | B26: =B5*B13*12 -> 2700 | C26: =B26 -> 2700 | D26: $/year
A27: Annual GPS / Telematics Cost | B27: =B5*B14*12 -> 12 | C27: =B27 -> 12 | D27: $/year
A28: Annual Registration / Tags | B28: =B5*B15 -> 250 | C28: =B28 -> 250 | D28: $/year
A29: Total Annual Vehicle Cost | B29: =SUM(C23:C28) -> 61233.164 | C29: =B29 -> 61233.164 | D29: $/year
A30: Vehicle Cost per Annual Labor Hour | B30: =IFERROR(C29/_Calc_Backend!$X$37,0) -> 3.5046454 | C30: =B30 -> 3.5046454 | D30: $/labor hr
A31: Vehicle Cost per Productive Coverage Hour | B31: =IFERROR(C29/_Calc_Backend!$X$33,0) -> 15.8425 | C31: =B31 -> 15.8425 | D31: $/coverage hr
A34: This tab calculates annual fleet cost and converts it into an hourly rate that feeds the Operations tab. Yellow cells are user inputs.

Sheet Training_Module
A1: Training Description | B1: Hours | C1: Training Wage | D1: Training Cost Per Hour | E1: Employees Trained | F1: Instructor Cost | G1: Equipment Cost | H1: Certification Fee | I1: Travel Cost | J1: Edit highlighted assumptions only
A2: CPR / First Aid / AED | B2: 8 | C2: 21 | D2: =C2/0.7 -> 30 | E2: =IFERROR(ROUNDUP(_Calc_Backend!$E$22/28,0),"") -> 12 | F2: 200 | G2: 600 | H2: 0 | I2: 0 | J2: =B2*D2*E2+F2+G2+H2+I2 -> 3680
A3: Pre‑Assignment Training | B3: 16 | C3: 25 | D3: =C3/0.7 -> 35.714286 | E3: =IFERROR(ROUNDUP(_Calc_Backend!$E$22/28,0),"") -> 12 | F3: 0 | G3: 0 | H3: 0 | I3: 0 | J3: =B3*D3*E3+F3+G3+H3+I3 -> 6857.1429
A4: Field Training | B4: 40 | C4: 21 | D4: =C4/0.7 -> 30 | E4: =IFERROR(ROUNDUP(_Calc_Backend!$E$22/28,0),"") -> 12 | F4: 0 | G4: 0 | H4: 0 | I4: 0 | J4: =B4*D4*E4+F4+G4+H4+I4 -> 14400
A5: Weapons Training | B5: 8 | C5: 21 | D5: =C5/0.7 -> 30 | E5: =IFERROR(ROUNDUP(_Calc_Backend!$E$22/28,0),"") -> 12 | F5: 0 | G5: 0 | H5: 0 | I5: 0 | J5: =B5*D5*E5+F5+G5+H5+I5 -> 2880
A6: Site Specific Training | B6: 8 | C6: 21 | D6: =C6/0.7 -> 30 | E6: =IFERROR(ROUNDUP(_Calc_Backend!$E$22/28,0),"") -> 12 | F6: 0 | G6: 0 | H6: 0 | I6: 0 | J6: =B6*D6*E6+F6+G6+H6+I6 -> 2880
A7: Supervisor Training | B7: 12 | C7: 25 | D7: =C7/0.7 -> 35.714286 | E7: =IFERROR(ROUNDUP(_Calc_Backend!$E$22/28,0),"") -> 12 | F7: 0 | G7: 0 | H7: 0 | I7: 0 | J7: =B7*D7*E7+F7+G7+H7+I7 -> 5142.8571
A8: Annual Refresher | B8: 8 | C8: 21 | D8: =C8/0.7 -> 30 | E8: =IFERROR(ROUNDUP(_Calc_Backend!$E$22/28,0),"") -> 12 | F8: 0 | G8: 0 | H8: 0 | I8: 0 | J8: =B8*D8*E8+F8+G8+H8+I8 -> 2880
I9: Total Training Cost | J9: =SUM(J2:J8) -> 38720

Sheet Equipment_Uniform_Module
A1: Item | B1: Cost Per Unit | C1: Quantity | D1: Replacement Cycle (Years) | E1: Annualized Cost
A2: Uniform | B2: 250 | C2: 4 | D2: 1 | E2: =B2*C2/D2 -> 1000
A3: Radio | B3: 600 | C3: 1 | D3: 3 | E3: =B3*C3/D3 -> 200
A4: Body Armor | B4: 800 | C4: 1 | D4: 5 | E4: =B4*C4/D4 -> 160
A5: Flashlight | B5: 75 | C5: 1 | D5: 2 | E5: =B5*C5/D5 -> 37.5
A6: Duty Belt | B6: 150 | C6: 1 | D6: 3 | E6: =B6*C6/D6 -> 50
D7: Total Annual Equipment Cost | E7: =SUM(E2:E6) -> 1447.5

Sheet Workforce_Maintenance_Module
A1: Category | B1: Days/Hours | C1: Employees | D1: Cost Per Hour | E1: Total Cost
A2: Vacation Days | B2: 80 | C2: 1 | D2: 28.04 | E2: =B2*C2*D2 -> 2243.2
A3: Sick Days | B3: 56 | C3: 2 | D3: 28.04 | E3: =B3*C3*D3 -> 3140.48
A4: Holiday Pay | B4: 88 | C4: 2 | D4: 42.06 | E4: =B4*C4*D4 -> 7402.56
A5: Turnover Replacement | B5: 40 | C5: 2 | D5: 28.04 | E5: =B5*C5*D5 -> 2243.2
A6: Recruiting / Hiring | B6: 0 | C6: 0 | D6: 0 | E6: =B6*C6*D6 -> 0
D7: Total Workforce Maintenance Cost | E7: =SUM(E2:E6) -> 15029.44

Sheet Direct_Labor
A1: GASQ Direct Labor Build-Up
A2: GASQ-branded operating model worksheet
A3: Line Item | B3: Input / Formula | C3: Hourly Amount | D3: Annual Amount
A4: Base Consolidated Blended Direct Labor Wage | B4: =IFERROR(IF(Post_Positions!$C$12>0,Post_Positions!$C$12,Inputs!$B$4),Inputs!$B$4) -> 33.74 | C4: =B4 -> 33.74 | D4: =C4*_Calc_Backend!$X$37 -> 589505.28
A5: Locality Pay | B5: =C4*Inputs!$B$7 -> 0 | C5: =B5 -> 0 | D5: =C5*_Calc_Backend!$X$37 -> 0
A6: Labor Market Adjustment | B6: =C4*Inputs!$B$10 -> 0 | C6: =B6 -> 0 | D6: =C6*_Calc_Backend!$X$37 -> 0
A7: H&W (Cash) | B7: =Inputs!$B$11 -> 4.22 | C7: =B7 -> 4.22 | D7: =C7*_Calc_Backend!$X$37 -> 73731.84
A8: Shift Differential | B8: =C4*Inputs!$B$8 -> 0 | C8: =B8 -> 0 | D8: =C8*_Calc_Backend!$X$37 -> 0
A9: OT/Holiday Premium | B9: =C4*Inputs!$B$9 -> 2.6992 | C9: =B9 -> 2.6992 | D9: =C9*_Calc_Backend!$X$37 -> 47160.422
A10: DON/DOFF | B10: =IFERROR(IF(Inputs!$B$21>0,SUM(C4:C9)*(Inputs!$B$21/480),0),0) -> 1.2706 | C10: =B10 -> 1.2706 | D10: =C10*_Calc_Backend!$X$37 -> 22199.923
A11: Total Direct Labor | C11: =SUM(C4:C10) -> 41.9298 | D11: =SUM(D4:D10) -> 732597.47
A12: Input (or weighted blended pay wage from Post_Positions only), plus locality, labor market, other direct-pay premiums, and DON/DOFF before burden is applied. | C12: =C11 -> 41.9298 | D12: =D11 -> 732597.47
A14: GASQ Fringe & Employer Burden
A15: GASQ-branded operating model worksheet
A16: Line Item | B16: Input / Formula | C16: Hourly Amount | D16: Annual Amount
A17: FICA / Medicare | B17: =Direct_Labor!$C$11*Inputs!$B$13 -> 3.2076297 | C17: =B17 -> 3.2076297 | D17: =C17*_Calc_Backend!$X$37 -> 56043.706
A18: FUTA | B18: =Direct_Labor!$C$11*Inputs!$B$14 -> 0.2515788 | C18: =B18 -> 0.2515788 | D18: =C18*_Calc_Backend!$X$37 -> 4395.5848
A19: SUTA | B19: =Direct_Labor!$C$11*Inputs!$B$15 -> 0.838596 | C19: =B19 -> 0.838596 | D19: =C19*_Calc_Backend!$X$37 -> 14651.949
A20: Workers Compensation | B20: =Direct_Labor!$C$11*Inputs!$B$16 -> 0.6708768 | C20: =B20 -> 0.6708768 | D20: =C20*_Calc_Backend!$X$37 -> 11721.559
A21: Health & Welfare | B21: =Inputs!$B$17 -> 0 | C21: =B21 -> 0 | D21: =C21*_Calc_Backend!$X$37 -> 0
A22: Vacation | B22: =Direct_Labor!$C$11*Inputs!$B$18 -> 0.838596 | C22: =B22 -> 0.838596 | D22: =C22*_Calc_Backend!$X$37 -> 14651.949
A23: Paid Holidays | B23: =Direct_Labor!$C$11*Inputs!$B$19 -> 1.677192 | C23: =B23 -> 1.677192 | D23: =C23*_Calc_Backend!$X$37 -> 29303.899
A24: Sick Leave | B24: =Direct_Labor!$C$11*Inputs!$B$20 -> 1.1321046 | C24: =B24 -> 1.1321046 | D24: =C24*_Calc_Backend!$X$37 -> 19780.132
A25: Total Fringe / Burden | C25: =SUM(C17:C24) -> 8.6165739 | D25: =SUM(D17:D24) -> 150548.78
A26: Total Direct Labor + Fringe | C26: =C11+C25 -> 50.546374 | D26: =D11+D25 -> 883146.24
A27: GASQ Operations & Contract Support (Integrated)
A28: GASQ-branded operating model worksheet
A29: Line Item | B29: Input / Formula | C29: Hourly Amount | D29: Annual Amount
A30: Recruiting / Hiring | B30: =Direct_Labor!$C$11*Inputs!$B$23 -> 0 | C30: =B30 -> 0 | D30: =C30*_Calc_Backend!$X$37 -> 0
A31: Training / Certification | B31: =Direct_Labor!$C$11*Inputs!$B$24 -> 0.628947 | C31: =B31 -> 0.628947 | D31: =C31*_Calc_Backend!$X$37 -> 10988.962
A32: Uniforms / Equipment | B32: =Uniform_Equipment!$C$36 -> 1.1071394 | C32: =B32 -> 1.1071394 | D32: =Uniform_Equipment!$C$35 -> 19343.94
A33: Field Supervision | B33: =Direct_Labor!$C$11*Inputs!$B$26 -> 0 | C33: =B33 -> 0 | D33: =C33*_Calc_Backend!$X$37 -> 0
A34: Contract Management | B34: =Direct_Labor!$C$11*Inputs!$B$27 -> 0 | C34: =B34 -> 0 | D34: =C34*_Calc_Backend!$X$37 -> 0
A35: Quality Assurance | B35: =Direct_Labor!$C$11*Inputs!$B$28 -> 0 | C35: =B35 -> 0 | D35: =C35*_Calc_Backend!$X$37 -> 0
A36: Vehicles / Patrol | B36: =Vehicle!$C$30 -> 3.5046454 | C36: =B36 -> 3.5046454 | D36: =Vehicle!$C$29 -> 61233.164
A37: Technology / Systems | B37: =Direct_Labor!$C$11*Inputs!$B$30 -> 0.419298 | C37: =B37 -> 0.419298 | D37: =C37*_Calc_Backend!$X$37 -> 7325.9747
A38: General Liability Insurance | B38: =Direct_Labor!$C$11*Inputs!$B$31 -> 3.7401382 | C38: =B38 -> 3.7401382 | D38: =C38*_Calc_Backend!$X$37 -> 65347.694
A39: Umbrella / Other Insurance | B39: =Direct_Labor!$C$11*Inputs!$B$32 -> 0.3144735 | C39: =B39 -> 0.3144735 | D39: =C39*_Calc_Backend!$X$37 -> 5494.481
A40: Total Operations / Support | C40: =SUM(C30:C39) -> 9.7146414 | D40: =SUM(D30:D39) -> 169734.22
A42: GASQ Overhead, G&A, and Profit (Integrated)
...

Sheet Appraisal_Full_Scope_Report
B1: GASQ Workforce-to-Post™ Capital Recovery Appraisal Full Scope Report
B2: Workforce Total Cost of Ownership (TCO) -vs- Vendor Outsourced Security Services
B3: Prepared for: | G3: =TODAY( ) -> 46118
B5: Appraisal Comparison Summary
B6: DESCRIPTION | F6: SERVICE REQUESTER INTERNAL TCO | H6: VENDOR TCO TO OUTSOURCE | J6: DIFFERENCE SAVED
B7: Workforce Baseline Assumption Labor Rate + Fringe Benefits | F7: =CFO_Bill_Rate_Breakdown!$B$24 -> 50.546374 | H7: =CFO_Bill_Rate_Breakdown!$B$24 -> 50.546374 | J7: =""
B8: Workforce Hourly Cost Per Security Professional | F8: =IFERROR(($F$7*Inputs!$B$44)/Inputs!$B$5,0) -> 129.97639 | H8: =IFERROR($F$8*Inputs!$B$40,0) -> 90.983473 | J8: =F8-H8 -> 38.992917
B9: Overtime/Holiday Rate | F9: =IFERROR(F8*1.5,0) -> 194.96459 | H9: =IFERROR(H8*1.5,0) -> 136.47521 | J9: =F9-H9 -> 58.489376
B10: Workforce Annual Cost per Security Professional | F10: =IFERROR(F8*Inputs!$B$5,0) -> 189245.62 | H10: =IFERROR(H8*Inputs!$B$5,0) -> 132471.94 | J10: =F10-H10 -> 56773.687
B11: Total Weekly Hours of Coverage | F11: =_Calc_Backend!$X$36 -> 336 | H11: =F11 -> 336 | J11: =""
B12: Total Monthly Hours of Coverage | F12: =Post_Positions!$F$12 -> 1456 | H12: =F12 -> 1456 | J12: =""
B13: Total Annual Hours of Coverage | F13: =_Calc_Backend!$X$33 -> 3865.12 | H13: =F13 -> 3865.12 | J13: =""
B14: Total Weeks of Coverage | F14: =Post_Positions!$D$12 -> 336 | H14: =F14 -> 336 | J14: =""
B15: Total Annual Hours of Coverage | F15: =Post_Positions!$H$12 -> 17472 | H15: =F15 -> 17472 | J15: =""
B16: Total Workforce Required for Coverage | F16: =_Calc_Backend!$X$38 -> 12 | H16: =F16 -> 12 | J16: =""
B17: Total Weekly Cost | F17: =IFERROR(F11*F8,0) -> 43672.067 | H17: =IFERROR(H11*H8,0) -> 30570.447 | J17: =F17-H17 -> 13101.62
B18: Total Monthly Cost | F18: =IFERROR(F12*F8,0) -> 189245.62 | H18: =IFERROR(H12*H8,0) -> 132471.94 | J18: =F18-H18 -> 56773.687
B19: Total Annual Cost | F19: =IFERROR(F8*F15,0) -> 2270947.5 | H19: =IFERROR(H8*H15,0) -> 1589663.2 | J19: =F19-H19 -> 681284.25
B20: Operational Capital Recovered | F20: ="" | H20: =J19 -> 681284.25 | J20: =""
B21: Operational Capital Recovered (%) | F21: ="" | H21: =IFERROR(H20/F19,0) -> 0.3 | J21: =""
B22: Payback & Recovery Period | H22: =IFERROR(H19/F18,0) -> 8.4 | J22: =""
B24: Coverage Statement
B25: All price calculations include the full cost of workforce staffing and support services, including but not limited to: livable base wages, employer-paid payroll taxes (FICA, FUTA, SUTA), workers’ compensation, general liability insurance, unemployment insurance, paid time off, healthcare and fringe benefits, uniforms and equipment, onboarding and training, site supervision, quality assurance oversight, management and administrative support, 24/7 dispatch capability, compliance with local, state, and federal labor laws, and all service-level guarantees (including open post protection, vendor replacement, and price lock guarantees) unless otherwise specified.
B28: "CFO Tested. CFO Approved"
B29: (470) 633-2816 | info@getasecurityquote.com | getasecurityquotenow.com
B30: Key Components of the GetASecurityQuote Security Capital Recovery Report
B31: Direct Labor Costs
B32: • Wages: Hourly pay for each guard (based on market, union scale, or livable wage rates)
B33: • Overtime: If scheduling exceeds 40 hours/week per guard or during holidays
B34: • Paid Non-Worked Hours: Includes holidays, sick leave, vacation, training
B35: Mandatory Payroll Burden
B36: • Employer Taxes: FICA, FUTA, SUTA, Medicare
B37: • Workers’ Compensation Insurance: Risk-rated by job classification (high for security)
... B68: Notes:

Sheet Additional Cost
A1: GASQ Additional Cost Stack
A2: Merged view of Vehicle, Uniform & Equipment, and Workforce Maintenance costs
A4: Module | B4: Source Tab | C4: Hourly Cost | D4: Annual Cost
A5: Vehicle / Patrol | B5: Vehicle | C5: =Vehicle!$C$30 -> 3.5046454 | D5: =Vehicle!$C$29 -> 61233.164
A6: Uniform & Equipment | B6: Uniform_Equipment | C6: =Uniform_Equipment!$C$36 -> 1.1071394 | D6: =Uniform_Equipment!$C$35 -> 19343.94
A7: Workforce Maintenance | B7: Workforce_Maintenance_Module | C7: =IFERROR(Workforce_Maintenance_Module!$E$7/_Calc_Backend!$X$37,0) -> 0.86020147 | D7: =Workforce_Maintenance_Module!$E$7 -> 15029.44
A8: Training | B8: Training_Module | C8: =IFERROR(Training_Module!$J$9/_Calc_Backend!$X$37,0) -> 2.2161172 | D8: =Training_Module!$J$9 -> 38720
A9: Total Additional Cost | C9: =SUM(C5:C8) -> 7.6881035 | D9: =SUM(D5:D8) -> 134326.54
A11: Note | B11: Source tabs remain in the workbook for audit support. Additional Cost is the consolidated operating view.

Sheet Option Year
A1: GASQ Option Year Analysis
A2: Base Year + Option Years 1-4 with hourly and annual cost by line item
A3: Escalation Scenario | B3: Medium | D3: Custom Escalation % | E3: =Inputs!$B$56 -> 0.03 | G3: Base Annual Hours | H3: =Appraisal_Full_Scope_Report!$F$15 -> 17472
A4: Applied Escalation % | B4: =IF($B$3="Low",Inputs!$B$58,IF($B$3="High",Inputs!$B$60,IF($B$3="Custom",Inputs!$B$56,Inputs!$B$59))) -> 0.03 | D4: Vendor Benchmark $/Hr | E4: =Appraisal_Full_Scope_Report!$F$8 -> 129.97639 | G4: Appraisal Vendor $/Hr | H4: =Appraisal_Full_Scope_Report!$H$8 -> 90.983473
A6: Description | B6: Base $/Hr | C6: Base Annual | D6: Opt Yr 1 $/Hr | E6: Opt Yr 1 Annual | F6: Opt Yr 2 $/Hr | G6: Opt Yr 2 Annual | H6: Opt Yr 3 $/Hr | I6: Opt Yr 3 Annual | J6: Opt Yr 4 $/Hr | K6: Opt Yr 4 Annual | L6: Total Contract Value | M6: Total Contract Value Avg $/Hr
A7: Direct Labor
A8: =CFO_Bill_Rate_Breakdown!A5 -> Base Consolidated Blended Direct Labor Wage | B8: =CFO_Bill_Rate_Breakdown!B5 -> 33.74 | C8: =CFO_Bill_Rate_Breakdown!C5 -> 589505.28 | D8: =IF(Inputs!$C$64="Manual",IF(OR($B8="",Inputs!$B$65=0,Inputs!$C$65=""),"",$B8*(Inputs!$C$65/Inputs!$B$65)),IF(OR($B8="",$B8=0),"",$B8*(1+$B$4)^1)) -> 34.7522 | E8: =IF(OR(D8="",D8=0,Inputs!$C$71=""),"",D8*Inputs!$C$71) -> 607190.44 | F8: =IF(Inputs!$D$64="Manual",IF(OR($B8="",Inputs!$B$65=0,Inputs!$D$65=""),"",$B8*(Inputs!$D$65/Inputs!$B$65)),IF(OR($B8="",$B8=0),"",$B8*(1+$B$4)^2)) -> 35.794766 | G8: =IF(OR(F8="",F8=0,Inputs!$D$71=""),"",F8*Inputs!$D$71) -> 625406.15 | H8: =IF(Inputs!$E$64="Manual",IF(OR($B8="",Inputs!$B$65=0,Inputs!$E$65=""),"",$B8*(Inputs!$E$65/Inputs!$B$65)),IF(OR($B8="",$B8=0),"",$B8*(1+$B$4)^3)) -> 36.868609 | I8: =IF(OR(H8="",H8=0,Inputs!$E$71=""),"",H8*Inputs!$E$71) -> 644168.34 | J8: =IF(Inputs!$F$64="Manual",IF(OR($B8="",Inputs!$B$65=0,Inputs!$F$65=""),"",$B8*(Inputs!$F$65/Inputs!$B$65)),IF(OR($B8="",$B8=0),"",$B8*(1+$B$4)^4)) -> 37.974667 | K8: =IF(OR(J8="",J8=0,Inputs!$F$71=""),"",J8*Inputs!$F$71) -> 663493.39 | L8: =SUM(C8,E8,G8,I8,K8) -> 3129763.6 | M8: =AVERAGE(B8,D8,F8,H8,J8) -> 35.826048
A9: =CFO_Bill_Rate_Breakdown!A6 -> Locality Pay | B9: =CFO_Bill_Rate_Breakdown!B6 -> 0 | C9: =CFO_Bill_Rate_Breakdown!C6 -> 0 | D9: =IF(Inputs!$C$64="Manual",IF(OR($B9="",Inputs!$B$65=0,Inputs!$C$65=""),"",$B9*(Inputs!$C$65/Inputs!$B$65)),IF(OR($B9="",$B9=0),"",$B9*(1+$B$4)^1)) | E9: =IF(OR(D9="",D9=0,Inputs!$C$71=""),"",D9*Inputs!$C$71) | F9: =IF(Inputs!$D$64="Manual",IF(OR($B9="",Inputs!$B$65=0,Inputs!$D$65=""),"",$B9*(Inputs!$D$65/Inputs!$B$65)),IF(OR($B9="",$B9=0),"",$B9*(1+$B$4)^2)) | G9: =IF(OR(F9="",F9=0,Inputs!$D$71=""),"",F9*Inputs!$D$71) | H9: =IF(Inputs!$E$64="Manual",IF(OR($B9="",Inputs!$B$65=0,Inputs!$E$65=""),"",$B9*(Inputs!$E$65/Inputs!$B$65)),IF(OR($B9="",$B9=0),"",$B9*(1+$B$4)^3)) | I9: =IF(OR(H9="",H9=0,Inputs!$E$71=""),"",H9*Inputs!$E$71) | J9: =IF(Inputs!$F$64="Manual",IF(OR($B9="",Inputs!$B$65=0,Inputs!$F$65=""),"",$B9*(Inputs!$F$65/Inputs!$B$65)),IF(OR($B9="",$B9=0),"",$B9*(1+$B$4)^4)) | K9: =IF(OR(J9="",J9=0,Inputs!$F$71=""),"",J9*Inputs!$F$71) | L9: =SUM(C9,E9,G9,I9,K9) -> 0 | M9: =AVERAGE(B9,D9,F9,H9,J9) -> 0
A10: =CFO_Bill_Rate_Breakdown!A7 -> Labor Market Adjustment | B10: =CFO_Bill_Rate_Breakdown!B7 -> 0 | C10: =CFO_Bill_Rate_Breakdown!C7 -> 0 | D10: =IF(Inputs!$C$64="Manual",IF(OR($B10="",Inputs!$B$65=0,Inputs!$C$65=""),"",$B10*(Inputs!$C$65/Inputs!$B$65)),IF(OR($B10="",$B10=0),"",$B10*(1+$B$4)^1)) | E10: =IF(OR(D10="",D10=0,Inputs!$C$71=""),"",D10*Inputs!$C$71) | F10: =IF(Inputs!$D$64="Manual",IF(OR($B10="",Inputs!$B$65=0,Inputs!$D$65=""),"",$B10*(Inputs!$D$65/Inputs!$B$65)),IF(OR($B10="",$B10=0),"",$B10*(1+$B$4)^2)) | G10: =IF(OR(F10="",F10=0,Inputs!$D$71=""),"",F10*Inputs!$D$71) | H10: =IF(Inputs!$E$64="Manual",IF(OR($B10="",Inputs!$B$65=0,Inputs!$E$65=""),"",$B10*(Inputs!$E$65/Inputs!$B$65)),IF(OR($B10="",$B10=0),"",$B10*(1+$B$4)^3)) | I10: =IF(OR(H10="",H10=0,Inputs!$E$71=""),"",H10*Inputs!$E$71) | J10: =IF(Inputs!$F$64="Manual",IF(OR($B10="",Inputs!$B$65=0,Inputs!$F$65=""),"",$B10*(Inputs!$F$65/Inputs!$B$65)),IF(OR($B10="",$B10=0),"",$B10*(1+$B$4)^4)) | K10: =IF(OR(J10="",J10=0,Inputs!$F$71=""),"",J10*Inputs!$F$71) | L10: =SUM(C10,E10,G10,I10,K10) -> 0 | M10: =AVERAGE(B10,D10,F10,H10,J10) -> 0
A11: =CFO_Bill_Rate_Breakdown!A8 -> H&W (Cash) | B11: =CFO_Bill_Rate_Breakdown!B8 -> 4.22 | C11: =CFO_Bill_Rate_Breakdown!C8 -> 73731.84 | D11: =IF(Inputs!$C$64="Manual",IF(OR($B11="",Inputs!$B$65=0,Inputs!$C$65=""),"",$B11*(Inputs!$C$65/Inputs!$B$65)),IF(OR($B11="",$B11=0),"",$B11*(1+$B$4)^1)) -> 4.3466 | E11: =IF(OR(D11="",D11=0,Inputs!$C$71=""),"",D11*Inputs!$C$71) -> 75943.795 | F11: =IF(Inputs!$D$64="Manual",IF(OR($B11="",Inputs!$B$65=0,Inputs!$D$65=""),"",$B11*(Inputs!$D$65/Inputs!$B$65)),IF(OR($B11="",$B11=0),"",$B11*(1+$B$4)^2)) -> 4.476998 | G11: =IF(OR(F11="",F11=0,Inputs!$D$71=""),"",F11*Inputs!$D$71) -> 78222.109 | H11: =IF(Inputs!$E$64="Manual",IF(OR($B11="",Inputs!$B$65=0,Inputs!$E$65=""),"",$B11*(Inputs!$E$65/Inputs!$B$65)),IF(OR($B11="",$B11=0),"",$B11*(1+$B$4)^3)) -> 4.6113079 | I11: =IF(OR(H11="",H11=0,Inputs!$E$71=""),"",H11*Inputs!$E$71) -> 80568.772 | J11: =IF(Inputs!$F$64="Manual",IF(OR($B11="",Inputs!$B$65=0,Inputs!$F$65=""),"",$B11*(Inputs!$F$65/Inputs!$B$65)),IF(OR($B11="",$B11=0),"",$B11*(1+$B$4)^4)) -> 4.7496472 | K11: =IF(OR(J11="",J11=0,Inputs!$F$71=""),"",J11*Inputs!$F$71) -> 82985.835 | L11: =SUM(C11,E11,G11,I11,K11) -> 391452.35 | M11: =AVERAGE(B11,D11,F11,H11,J11) -> 4.4809106
A12: =CFO_Bill_Rate_Breakdown!A9 -> Shift Differential | B12: =CFO_Bill_Rate_Breakdown!B9 -> 0 | C12: =CFO_Bill_Rate_Breakdown!C9 -> 0 | D12: =IF(Inputs!$C$64="Manual",IF(OR($B12="",Inputs!$B$65=0,Inputs!$C$65=""),"",$B12*(Inputs!$C$65/Inputs!$B$65)),IF(OR($B12="",$B12=0),"",$B12*(1+$B$4)^1)) | E12: =IF(OR(D12="",D12=0,Inputs!$C$71=""),"",D12*Inputs!$C$71) | F12: =IF(Inputs!$D$64="Manual",IF(OR($B12="",Inputs!$B$65=0,Inputs!$D$65=""),"",$B12*(Inputs!$D$65/Inputs!$B$65)),IF(OR($B12="",$B12=0),"",$B12*(1+$B$4)^2)) | G12: =IF(OR(F12="",F12=0,Inputs!$D$71=""),"",F12*Inputs!$D$71) | H12: =IF(Inputs!$E$64="Manual",IF(OR($B12="",Inputs!$B$65=0,Inputs!$E$65=""),"",$B12*(Inputs!$E$65/Inputs!$B$65)),IF(OR($B12="",$B12=0),"",$B12*(1+$B$4)^3)) | I12: =IF(OR(H12="",H12=0,Inputs!$E$71=""),"",H12*Inputs!$E$71) | J12: =IF(Inputs!$F$64="Manual",IF(OR($B12="",Inputs!$B$65=0,Inputs!$F$65=""),"",$B12*(Inputs!$F$65/Inputs!$B$65)),IF(OR($B12="",$B12=0),"",$B12*(1+$B$4)^4)) | K12: =IF(OR(J12="",J12=0,Inputs!$F$71=""),"",J12*Inputs!$F$71) | L12: =SUM(C12,E12,G12,I12,K12) -> 0 | M12: =AVERAGE(B12,D12,F12,H12,J12) -> 0
A13: =CFO_Bill_Rate_Breakdown!A10 -> OT/Holiday Premium | B13: =CFO_Bill_Rate_Breakdown!B10 -> 2.6992 | C13: =CFO_Bill_Rate_Breakdown!C10 -> 47160.422 | D13: =IF(Inputs!$C$64="Manual",IF(OR($B13="",Inputs!$B$65=0,Inputs!$C$65=""),"",$B13*(Inputs!$C$65/Inputs!$B$65)),IF(OR($B13="",$B13=0),"",$B13*(1+$B$4)^1)) -> 2.780176 | E13: =IF(OR(D13="",D13=0,Inputs!$C$71=""),"",D13*Inputs!$C$71) -> 48575.235 | F13: =IF(Inputs!$D$64="Manual",IF(OR($B13="",Inputs!$B$65=0,Inputs!$D$65=""),"",$B13*(Inputs!$D$65/Inputs!$B$65)),IF(OR($B13="",$B13=0),"",$B13*(1+$B$4)^2)) -> 2.8635813 | G13: =IF(OR(F13="",F13=0,Inputs!$D$71=""),"",F13*Inputs!$D$71) -> 50032.492 | H13: =IF(Inputs!$E$64="Manual",IF(OR($B13="",Inputs!$B$65=0,Inputs!$E$65=""),"",$B13*(Inputs!$E$65/Inputs!$B$65)),IF(OR($B13="",$B13=0),"",$B13*(1+$B$4)^3)) -> 2.9494887 | I13: =IF(OR(H13="",H13=0,Inputs!$E$71=""),"",H13*Inputs!$E$71) -> 51533.467 | J13: =IF(Inputs!$F$64="Manual",IF(OR($B13="",Inputs!$B$65=0,Inputs!$F$65=""),"",$B13*(Inputs!$F$65/Inputs!$B$65)),IF(OR($B13="",$B13=0),"",$B13*(1+$B$4)^4)) -> 3.0379734 | K13: =IF(OR(J13="",J13=0,Inputs!$F$71=""),"",J13*Inputs!$F$71) -> 53079.471 | L13: =SUM(C13,E13,G13,I13,K13) -> 250381.09 | M13: =AVERAGE(B13,D13,F13,H13,J13) -> 2.8660839
A14: =CFO_Bill_Rate_Breakdown!A11 -> DON/DOFF | B14: =CFO_Bill_Rate_Breakdown!B11 -> 1.2706 | C14: =CFO_Bill_Rate_Breakdown!C11 -> 22199.923 | D14: =IF(Inputs!$C$64="Manual",IF(OR($B14="",Inputs!$B$65=0,Inputs!$C$65=""),"",$B14*(Inputs!$C$65/Inputs!$B$65)),IF(OR($B14="",$B14=0),"",$B14*(1+$B$4)^1)) -> 1.308718 | E14: =IF(OR(D14="",D14=0,Inputs!$C$71=""),"",D14*Inputs!$C$71) -> 22865.921 | F14: =IF(Inputs!$D$64="Manual",IF(OR($B14="",Inputs!$B$65=0,Inputs!$D$65=""),"",$B14*(Inputs!$D$65/Inputs!$B$65)),IF(OR($B14="",$B14=0),"",$B14*(1+$B$4)^2)) -> 1.3479795 | G14: =IF(OR(F14="",F14=0,Inputs!$D$71=""),"",F14*Inputs!$D$71) -> 23551.899 | H14: =IF(Inputs!$E$64="Manual",IF(OR($B14="",Inputs!$B$65=0,Inputs!$E$65=""),"",$B14*(Inputs!$E$65/Inputs!$B$65)),IF(OR($B14="",$B14=0),"",$B14*(1+$B$4)^3)) -> 1.3884189 | I14: =IF(OR(H14="",H14=0,Inputs!$E$71=""),"",H14*Inputs!$E$71) -> 24258.455 | J14: =IF(Inputs!$F$64="Manual",IF(OR($B14="",Inputs!$B$65=0,Inputs!$F$65=""),"",$B14*(Inputs!$F$65/Inputs!$B$65)),IF(OR($B14="",$B14=0),"",$B14*(1+$B$4)^4)) -> 1.4300715 | K14: =IF(OR(J14="",J14=0,Inputs!$F$71=""),"",J14*Inputs!$F$71) -> 24986.209 | L14: =SUM(C14,E14,G14,I14,K14) -> 117862.41 | M14: =AVERAGE(B14,D14,F14,H14,J14) -> 1.3491576
A15: =CFO_Bill_Rate_Breakdown!A12 -> Total Direct Labor | B15: =CFO_Bill_Rate_Breakdown!B12 -> 41.9298 | C15: =CFO_Bill_Rate_Breakdown!C12 -> 732597.47 | D15: =IF(Inputs!$C$64="Manual",IF(OR($B15="",Inputs!$B$65=0,Inputs!$C$65=""),"",$B15*(Inputs!$C$65/Inputs!$B$65)),IF(OR($B15="",$B15=0),"",$B15*(1+$B$4)^1)) -> 43.187694 | E15: =IF(OR(D15="",D15=0,Inputs!$C$71=""),"",D15*Inputs!$C$71) -> 754575.39 | F15: =IF(Inputs!$D$64="Manual",IF(OR($B15="",Inputs!$B$65=0,Inputs!$D$65=""),"",$B15*(Inputs!$D$65/Inputs!$B$65)),IF(OR($B15="",$B15=0),"",$B15*(1+$B$4)^2)) -> 44.483325 | G15: =IF(OR(F15="",F15=0,Inputs!$D$71=""),"",F15*Inputs!$D$71) -> 777212.65 | H15: =IF(Inputs!$E$64="Manual",IF(OR($B15="",Inputs!$B$65=0,Inputs!$E$65=""),"",$B15*(Inputs!$E$65/Inputs!$B$65)),IF(OR($B15="",$B15=0),"",$B15*(1+$B$4)^3)) -> 45.817825 | I15: =IF(OR(H15="",H15=0,Inputs!$E$71=""),"",H15*Inputs!$E$71) -> 800529.03 | J15: =IF(Inputs!$F$64="Manual",IF(OR($B15="",Inputs!$B$65=0,Inputs!$F$65=""),"",$B15*(Inputs!$F$65/Inputs!$B$65)),IF(OR($B15="",$B15=0),"",$B15*(1+$B$4)^4)) -> 47.192359 | K15: =IF(OR(J15="",J15=0,Inputs!$F$71=""),"",J15*Inputs!$F$71) -> 824544.9 | L15: =SUM(C15,E15,G15,I15,K15) -> 3889459.4 | M15: =AVERAGE(B15,D15,F15,H15,J15) -> 44.522201
A16: Fringe / Employer Burden
A17: =CFO_Bill_Rate_Breakdown!A15 -> FICA / Medicare | B17: =CFO_Bill_Rate_Breakdown!B15 -> 3.2076297 | C17: =CFO_Bill_Rate_Breakdown!C15 -> 56043.706 | D17: =IF(Inputs!$C$64="Manual",IF(OR($B17="",Inputs!$B$65=0,Inputs!$C$65=""),"",$B17*(Inputs!$C$65/Inputs!$B$65)),IF(OR($B17="",$B17=0),"",$B17*(1+$B$4)^1)) -> 3.3038586 | E17: =IF(OR(D17="",D17=0,Inputs!$C$71=""),"",D17*Inputs!$C$71) -> 57725.017 | F17: =IF(Inputs!$D$64="Manual",IF(OR($B17="",Inputs!$B$65=0,Inputs!$D$65=""),"",$B17*(Inputs!$D$65/Inputs!$B$65)),IF(OR($B17="",$B17=0),"",$B17*(1+$B$4)^2)) -> 3.4029743 | G17: =IF(OR(F17="",F17=0,Inputs!$D$71=""),"",F17*Inputs!$D$71) -> 59456.768 | H17: =IF(Inputs!$E$64="Manual",IF(OR($B17="",Inputs!$B$65=0,Inputs!$E$65=""),"",$B17*(Inputs!$E$65/Inputs!$B$65)),IF(OR($B17="",$B17=0),"",$B17*(1+$B$4)^3)) -> 3.5050636 | I17: =IF(OR(H17="",H17=0,Inputs!$E$71=""),"",H17*Inputs!$E$71) -> 61240.471 | J17: =IF(Inputs!$F$64="Manual",IF(OR($B17="",Inputs!$B$65=0,Inputs!$F$65=""),"",$B17*(Inputs!$F$65/Inputs!$B$65)),IF(OR($B17="",$B17=0),"",$B17*(1+$B$4)^4)) -> 3.6102155 | K17: =IF(OR(J17="",J17=0,Inputs!$F$71=""),"",J17*Inputs!$F$71) -> 63077.685 | L17: =SUM(C17,E17,G17,I17,K17) -> 297543.65 | M17: =AVERAGE(B17,D17,F17,H17,J17) -> 3.4059483
A18: =CFO_Bill_Rate_Breakdown!A16 -> FUTA | B18: =CFO_Bill_Rate_Breakdown!B16 -> 0.2515788 | C18: =CFO_Bill_Rate_Breakdown!C16 -> 4395.5848 | D18: =IF(Inputs!$C$64="Manual",IF(OR($B18="",Inputs!$B$65=0,Inputs!$C$65=""),"",$B18*(Inputs!$C$65/Inputs!$B$65)),IF(OR($B18="",$B18=0),"",$B18*(1+$B$4)^1)) -> 0.25912616 | E18: =IF(OR(D18="",D18=0,Inputs!$C$71=""),"",D18*Inputs!$C$71) -> 4527.4523 | F18: =IF(Inputs!$D$64="Manual",IF(OR($B18="",Inputs!$B$65=0,Inputs!$D$65=""),"",$B18*(Inputs!$D$65/Inputs!$B$65)),IF(OR($B18="",$B18=0),"",$B18*(1+$B$4)^2)) -> 0.26689995 | G18: =IF(OR(F18="",F18=0,Inputs!$D$71=""),"",F18*Inputs!$D$71) -> 4663.2759 | H18: =IF(Inputs!$E$64="Manual",IF(OR($B18="",Inputs!$B$65=0,Inputs!$E$65=""),"",$B18*(Inputs!$E$65/Inputs!$B$65)),IF(OR($B18="",$B18=0),"",$B18*(1+$B$4)^3)) -> 0.27490695 | I18: =IF(OR(H18="",H18=0,Inputs!$E$71=""),"",H18*Inputs!$E$71) -> 4803.1742 | J18: =IF(Inputs!$F$64="Manual",IF(OR($B18="",Inputs!$B$65=0,Inputs!$F$65=""),"",$B18*(Inputs!$F$65/Inputs!$B$65)),IF(OR($B18="",$B18=0),"",$B18*(1+$B$4)^4)) -> 0.28315416 | K18: =IF(OR(J18="",J18=0,Inputs!$F$71=""),"",J18*Inputs!$F$71) -> 4947.2694 | L18: =SUM(C18,E18,G18,I18,K18) -> 23336.757 | M18: =AVERAGE(B18,D18,F18,H18,J18) -> 0.2671332
A19: =CFO_Bill_Rate_Breakdown!A17 -> SUTA | B19: =CFO_Bill_Rate_Breakdown!B17 -> 0.838596 | C19: =CFO_Bill_Rate_Breakdown!C17 -> 14651.949 | D19: =IF(Inputs!$C$64="Manual",IF(OR($B19="",Inputs!$B$65=0,Inputs!$C$65=""),"",$B19*(Inputs!$C$65/Inputs!$B$65)),IF(OR($B19="",$B19=0),"",$B19*(1+$B$4)^1)) -> 0.86375388 | E19: =IF(OR(D19="",D19=0,Inputs!$C$71=""),"",D19*Inputs!$C$71) -> 15091.508 | F19: =IF(Inputs!$D$64="Manual",IF(OR($B19="",Inputs!$B$65=0,Inputs!$D$65=""),"",$B19*(Inputs!$D$65/Inputs!$B$65)),IF(OR($B19="",$B19=0),"",$B19*(1+$B$4)^2)) -> 0.8896665 | G19: =IF(OR(F19="",F19=0,Inputs!$D$71=""),"",F19*Inputs!$D$71) -> 15544.253 | H19: =IF(Inputs!$E$64="Manual",IF(OR($B19="",Inputs!$B$65=0,Inputs!$E$65=""),"",$B19*(Inputs!$E$65/Inputs!$B$65)),IF(OR($B19="",$B19=0),"",$B19*(1+$B$4)^3)) -> 0.91635649 | I19: =IF(OR(H19="",H19=0,Inputs!$E$71=""),"",H19*Inputs!$E$71) -> 16010.581 | J19: =IF(Inputs!$F$64="Manual",IF(OR($B19="",Inputs!$B$65=0,Inputs!$F$65=""),"",$B19*(Inputs!$F$65/Inputs!$B$65)),IF(OR($B19="",$B19=0),"",$B19*(1+$B$4)^4)) -> 0.94384719 | K19: =IF(OR(J19="",J19=0,Inputs!$F$71=""),"",J19*Inputs!$F$71) -> 16490.898 | L19: =SUM(C19,E19,G19,I19,K19) -> 77789.189 | M19: =AVERAGE(B19,D19,F19,H19,J19) -> 0.89044401
A20: =CFO_Bill_Rate_Breakdown!A18 -> Workers Compensation | B20: =CFO_Bill_Rate_Breakdown!B18 -> 0.6708768 | C20: =CFO_Bill_Rate_Breakdown!C18 -> 11721.559 | D20: =IF(Inputs!$C$64="Manual",IF(OR($B20="",Inputs!$B$65=0,Inputs!$C$65=""),"",$B20*(Inputs!$C$65/Inputs!$B$65)),IF(OR($B20="",$B20=0),"",$B20*(1+$B$4)^1)) -> 0.6910031 | E20: =IF(OR(D20="",D20=0,Inputs!$C$71=""),"",D20*Inputs!$C$71) -> 12073.206 | F20: =IF(Inputs!$D$64="Manual",IF(OR($B20="",Inputs!$B$65=0,Inputs!$D$65=""),"",$B20*(Inputs!$D$65/Inputs!$B$65)),IF(OR($B20="",$B20=0),"",$B20*(1+$B$4)^2)) -> 0.7117332 | G20: =IF(OR(F20="",F20=0,Inputs!$D$71=""),"",F20*Inputs!$D$71) -> 12435.402 | H20: =IF(Inputs!$E$64="Manual",IF(OR($B20="",Inputs!$B$65=0,Inputs!$E$65=""),"",$B20*(Inputs!$E$65/Inputs!$B$65)),IF(OR($B20="",$B20=0),"",$B20*(1+$B$4)^3)) -> 0.73308519 | I20: =IF(OR(H20="",H20=0,Inputs!$E$71=""),"",H20*Inputs!$E$71) -> 12808.464 | J20: =IF(Inputs!$F$64="Manual",IF(OR($B20="",Inputs!$B$65=0,Inputs!$F$65=""),"",$B20*(Inputs!$F$65/Inputs!$B$65)),IF(OR($B20="",$B20=0),"",$B20*(1+$B$4)^4)) -> 0.75507775 | K20: =IF(OR(J20="",J20=0,Inputs!$F$71=""),"",J20*Inputs!$F$71) -> 13192.718 | L20: =SUM(C20,E20,G20,I20,K20) -> 62231.351 | M20: =AVERAGE(B20,D20,F20,H20,J20) -> 0.71235521
A21: =CFO_Bill_Rate_Breakdown!A19 -> Health & Welfare | B21: =CFO_Bill_Rate_Breakdown!B19 -> 0 | C21: =CFO_Bill_Rate_Breakdown!C19 -> 0 | D21: =IF(Inputs!$C$64="Manual",IF(OR($B21="",Inputs!$B$65=0,Inputs!$C$65=""),"",$B21*(Inputs!$C$65/Inputs!$B$65)),IF(OR($B21="",$B21=0),"",$B21*(1+$B$4)^1)) | E21: =IF(OR(D21="",D21=0,Inputs!$C$71=""),"",D21*Inputs!$C$71) | F21: =IF(Inputs!$D$64="Manual",IF(OR($B21="",Inputs!$B$65=0,Inputs!$D$65=""),"",$B21*(Inputs!$D$65/Inputs!$B$65)),IF(OR($B21="",$B21=0),"",$B21*(1+$B$4)^2)) | G21: =IF(OR(F21="",F21=0,Inputs!$D$71=""),"",F21*Inputs!$D$71) | H21: =IF(Inputs!$E$64="Manual",IF(OR($B21="",Inputs!$B$65=0,Inputs!$E$65=""),"",$B21*(Inputs!$E$65/Inputs!$B$65)),IF(OR($B21="",$B21=0),"",$B21*(1+$B$4)^3)) | I21: =IF(OR(H21="",H21=0,Inputs!$E$71=""),"",H21*Inputs!$E$71) | J21: =IF(Inputs!$F$64="Manual",IF(OR($B21="",Inputs!$B$65=0,Inputs!$F$65=""),"",$B21*(Inputs!$F$65/Inputs!$B$65)),IF(OR($B21="",$B21=0),"",$B21*(1+$B$4)^4)) | K21: =IF(OR(J21="",J21=0,Inputs!$F$71=""),"",J21*Inputs!$F$71) | L21: =SUM(C21,E21,G21,I21,K21) -> 0 | M21: =AVERAGE(B21,D21,F21,H21,J21) -> 0
A22: =CFO_Bill_Rate_Breakdown!A20 -> Vacation | B22: =CFO_Bill_Rate_Breakdown!B20 -> 0.838596 | C22: =CFO_Bill_Rate_Breakdown!C20 -> 14651.949 | D22: =IF(Inputs!$C$64="Manual",IF(OR($B22="",Inputs!$B$65=0,Inputs!$C$65=""),"",$B22*(Inputs!$C$65/Inputs!$B$65)),IF(OR($B22="",$B22=0),"",$B22*(1+$B$4)^1)) -> 0.86375388 | E22: =IF(OR(D22="",D22=0,Inputs!$C$71=""),"",D22*Inputs!$C$71) -> 15091.508 | F22: =IF(Inputs!$D$64="Manual",IF(OR($B22="",Inputs!$B$65=0,Inputs!$D$65=""),"",$B22*(Inputs!$D$65/Inputs!$B$65)),IF(OR($B22="",$B22=0),"",$B22*(1+$B$4)^2)) -> 0.8896665 | G22: =IF(OR(F22="",F22=0,Inputs!$D$71=""),"",F22*Inputs!$D$71) -> 15544.253 | H22: =IF(Inputs!$E$64="Manual",IF(OR($B22="",Inputs!$B$65=0,Inputs!$E$65=""),"",$B22*(Inputs!$E$65/Inputs!$B$65)),IF(OR($B22="",$B22=0),"",$B22*(1+$B$4)^3)) -> 0.91635649 | I22: =IF(OR(H22="",H22=0,Inputs!$E$71=""),"",H22*Inputs!$E$71) -> 16010.581 | J22: =IF(Inputs!$F$64="Manual",IF(OR($B22="",Inputs!$B$65=0,Inputs!$F$65=""),"",$B22*(Inputs!$F$65/Inputs!$B$65)),IF(OR($B22="",$B22=0),"",$B22*(1+$B$4)^4)) -> 0.94384719 | K22: =IF(OR(J22="",J22=0,Inputs!$F$71=""),"",J22*Inputs!$F$71) -> 16490.898 | L22: =SUM(C22,E22,G22,I22,K22) -> 77789.189 | M22: =AVERAGE(B22,D22,F22,H22,J22) -> 0.89044401
A23: =CFO_Bill_Rate_Breakdown!A21 -> Paid Holidays | B23: =CFO_Bill_Rate_Breakdown!B21 -> 1.677192 | C23: =CFO_Bill_Rate_Breakdown!C21 -> 29303.899 | D23: =IF(Inputs!$C$64="Manual",IF(OR($B23="",Inputs!$B$65=0,Inputs!$C$65=""),"",$B23*(Inputs!$C$65/Inputs!$B$65)),IF(OR($B23="",$B23=0),"",$B23*(1+$B$4)^1)) -> 1.7275078 | E23: =IF(OR(D23="",D23=0,Inputs!$C$71=""),"",D23*Inputs!$C$71) -> 30183.016 | F23: =IF(Inputs!$D$64="Manual",IF(OR($B23="",Inputs!$B$65=0,Inputs!$D$65=""),"",$B23*(Inputs!$D$65/Inputs!$B$65)),IF(OR($B23="",$B23=0),"",$B23*(1+$B$4)^2)) -> 1.779333 | G23: =IF(OR(F23="",F23=0,Inputs!$D$71=""),"",F23*Inputs!$D$71) -> 31088.506 | H23: =IF(Inputs!$E$64="Manual",IF(OR($B23="",Inputs!$B$65=0,Inputs!$E$65=""),"",$B23*(Inputs!$E$65/Inputs!$B$65)),IF(OR($B23="",$B23=0),"",$B23*(1+$B$4)^3)) -> 1.832713 | I23: =IF(OR(H23="",H23=0,Inputs!$E$71=""),"",H23*Inputs!$E$71) -> 32021.161 | J23: =IF(Inputs!$F$64="Manual",IF(OR($B23="",Inputs!$B$65=0,Inputs!$F$65=""),"",$B23*(Inputs!$F$65/Inputs!$B$65)),IF(OR($B23="",$B23=0),"",$B23*(1+$B$4)^4)) -> 1.8876944 | K23: =IF(OR(J23="",J23=0,Inputs!$F$71=""),"",J23*Inputs!$F$71) -> 32981.796 | L23: =SUM(C23,E23,G23,I23,K23) -> 155578.38 | M23: =AVERAGE(B23,D23,F23,H23,J23) -> 1.780888
A24: =CFO_Bill_Rate_Breakdown!A22 -> Sick Leave | B24: =CFO_Bill_Rate_Breakdown!B22 -> 1.1321046 | C24: =CFO_Bill_Rate_Breakdown!C22 -> 19780.132 | D24: =IF(Inputs!$C$64="Manual",IF(OR($B24="",Inputs!$B$65=0,Inputs!$C$65=""),"",$B24*(Inputs!$C$65/Inputs!$B$65)),IF(OR($B24="",$B24=0),"",$B24*(1+$B$4)^1)) -> 1.1660677 | E24: =IF(OR(D24="",D24=0,Inputs!$C$71=""),"",D24*Inputs!$C$71) -> 20373.536 | F24: =IF(Inputs!$D$64="Manual",IF(OR($B24="",Inputs!$B$65=0,Inputs!$D$65=""),"",$B24*(Inputs!$D$65/Inputs!$B$65)),IF(OR($B24="",$B24=0),"",$B24*(1+$B$4)^2)) -> 1.2010498 | G24: =IF(OR(F24="",F24=0,Inputs!$D$71=""),"",F24*Inputs!$D$71) -> 20984.742 | H24: =IF(Inputs!$E$64="Manual",IF(OR($B24="",Inputs!$B$65=0,Inputs!$E$65=""),"",$B24*(Inputs!$E$65/Inputs!$B$65)),IF(OR($B24="",$B24=0),"",$B24*(1+$B$4)^3)) -> 1.2370813 | I24: =IF(OR(H24="",H24=0,Inputs!$E$71=""),"",H24*Inputs!$E$71) -> 21614.284 | J24: =IF(Inputs!$F$64="Manual",IF(OR($B24="",Inputs!$B$65=0,Inputs!$F$65=""),"",$B24*(Inputs!$F$65/Inputs!$B$65)),IF(OR($B24="",$B24=0),"",$B24*(1+$B$4)^4)) -> 1.2741937 | K24: =IF(OR(J24="",J24=0,Inputs!$F$71=""),"",J24*Inputs!$F$71) -> 22262.712 | L24: =SUM(C24,E24,G24,I24,K24) -> 105015.4 | M24: =AVERAGE(B24,D24,F24,H24,J24) -> 1.2020994
A25: =CFO_Bill_Rate_Breakdown!A23 -> Total Fringe / Burden | B25: =CFO_Bill_Rate_Breakdown!B23 -> 8.6165739 | C25: =CFO_Bill_Rate_Breakdown!C23 -> 150548.78 | D25: =IF(Inputs!$C$64="Manual",IF(OR($B25="",Inputs!$B$65=0,Inputs!$C$65=""),"",$B25*(Inputs!$C$65/Inputs!$B$65)),IF(OR($B25="",$B25=0),"",$B25*(1+$B$4)^1)) -> 8.8750711 | E25: =IF(OR(D25="",D25=0,Inputs!$C$71=""),"",D25*Inputs!$C$71) -> 155065.24 | F25: =IF(Inputs!$D$64="Manual",IF(OR($B25="",Inputs!$B$65=0,Inputs!$D$65=""),"",$B25*(Inputs!$D$65/Inputs!$B$65)),IF(OR($B25="",$B25=0),"",$B25*(1+$B$4)^2)) -> 9.1413233 | G25: =IF(OR(F25="",F25=0,Inputs!$D$71=""),"",F25*Inputs!$D$71) -> 159717.2 | H25: =IF(Inputs!$E$64="Manual",IF(OR($B25="",Inputs!$B$65=0,Inputs!$E$65=""),"",$B25*(Inputs!$E$65/Inputs!$B$65)),IF(OR($B25="",$B25=0),"",$B25*(1+$B$4)^3)) -> 9.4155629 | I25: =IF(OR(H25="",H25=0,Inputs!$E$71=""),"",H25*Inputs!$E$71) -> 164508.72 | J25: =IF(Inputs!$F$64="Manual",IF(OR($B25="",Inputs!$B$65=0,Inputs!$F$65=""),"",$B25*(Inputs!$F$65/Inputs!$B$65)),IF(OR($B25="",$B25=0),"",$B25*(1+$B$4)^4)) -> 9.6980298 | K25: =IF(OR(J25="",J25=0,Inputs!$F$71=""),"",J25*Inputs!$F$71) -> 169443.98 | L25: =SUM(C25,E25,G25,I25,K25) -> 799283.91 | M25: =AVERAGE(B25,D25,F25,H25,J25) -> 9.1493122
A26: =CFO_Bill_Rate_Breakdown!A24 -> Total Direct Labor + Fringe | B26: =CFO_Bill_Rate_Breakdown!B24 -> 50.546374 | C26: =CFO_Bill_Rate_Breakdown!C24 -> 883146.24 | D26: =IF(Inputs!$C$64="Manual",IF(OR($B26="",Inputs!$B$65=0,Inputs!$C$65=""),"",$B26*(Inputs!$C$65/Inputs!$B$65)),IF(OR($B26="",$B26=0),"",$B26*(1+$B$4)^1)) -> 52.062765 | E26: =IF(OR(D26="",D26=0,Inputs!$C$71=""),"",D26*Inputs!$C$71) -> 909640.63 | F26: =IF(Inputs!$D$64="Manual",IF(OR($B26="",Inputs!$B$65=0,Inputs!$D$65=""),"",$B26*(Inputs!$D$65/Inputs!$B$65)),IF(OR($B26="",$B26=0),"",$B26*(1+$B$4)^2)) -> 53.624648 | G26: =IF(OR(F26="",F26=0,Inputs!$D$71=""),"",F26*Inputs!$D$71) -> 936929.85 | H26: =IF(Inputs!$E$64="Manual",IF(OR($B26="",Inputs!$B$65=0,Inputs!$E$65=""),"",$B26*(Inputs!$E$65/Inputs!$B$65)),IF(OR($B26="",$B26=0),"",$B26*(1+$B$4)^3)) -> 55.233388 | I26: =IF(OR(H26="",H26=0,Inputs!$E$71=""),"",H26*Inputs!$E$71) -> 965037.75 | J26: =IF(Inputs!$F$64="Manual",IF(OR($B26="",Inputs!$B$65=0,Inputs!$F$65=""),"",$B26*(Inputs!$F$65/Inputs!$B$65)),IF(OR($B26="",$B26=0),"",$B26*(1+$B$4)^4)) -> 56.890389 | K26: =IF(OR(J26="",J26=0,Inputs!$F$71=""),"",J26*Inputs!$F$71) -> 993988.88 | L26: =SUM(C26,E26,G26,I26,K26) -> 4688743.4 | M26: =AVERAGE(B26,D26,F26,H26,J26) -> 53.671513
A27: Operations / Support | L27: =IFERROR(SUM(C27:G27),0) -> 0 | M27: =IFERROR(L27/H27,0) -> 0
